Workbook

Sheet 📘 사용안내
A1: 📘 EVEREST RESTAURANT GROUP · 메뉴 원가 분석서
A2: 레시피북 v3 (87종) + 식재료/고정비 DB · v2.0
A4: ▸ 이 파일의 구조
B5: ① 식재료 단가 | C5: 식재료 118종의 구매가격 → g당 단가. 여기만 고치면 모든 메뉴 원가가 따라 바뀝니다.
B6: ② 프렙 원가 | C6: 커리 그레이비·탄두리 소스 등 반제품 11종의 g당 원가. 프렙 안에 프렙이 들어가도 자동 계산됩니다.
B7: ③ 고정비 설정 | C7: 월 고정비·월 추정매출·판정 기준. 고정비 배분율이 여기서 결정됩니다.
B8: ④ 메뉴 원가표 | C8: 메뉴 87종의 판매가·원가·원가율·마진 한눈에. 판매가만 입력하면 됩니다.
B9: ⑤ 레시피 상세 | C9: 레시피북과 똑같은 재료·사용량. 한 줄 = 재료 1개의 단일 서식입니다.
B10: ⑥ 분석 대시보드 | C10: KPI·카테고리별 원가율·개선 우선순위 TOP10. 전부 수식이라 자동 갱신됩니다.
B11: ⚠ 확인 필요 | C11: 값이 비었거나 추정한 항목 목록. 채워 넣을수록 정확해집니다.
A13: ▸ 색상 규칙
B14: 노란 셀 | C14: 직접 입력하는 값 (구매가격, 사용량, 판매가, 고정비 …)
B15: 회색 셀 | C15: 수식이 자동 계산하는 값 — 덮어쓰지 마세요
B16: ✅ 양호 | C16: 식재료 원가율이 목표(기본 30%) 이하
B17: 🟡 주의 | C17: 목표 초과 ~ 주의선(기본 38%) 이하
B18: 🔴 과다 | C18: 주의선 초과 — 레시피·판매가 재검토 필요
A20: ▸ 계산 방식
B21: 단가 | C21: 무게 품목: 구매가격 ÷ 총중량(g) → 원/g · 개수 품목: 구매가격 ÷ 규격수량 → 원/개
B22: 재료비 | C22: 사용량 ÷ 수율 × g당 단가 (수율 100% 면 사용량 × 단가)
B23: 프렙 g당 원가 | C23: 프렙 총 재료비 ÷ 완성중량(g)
B24: 식재료 원가 | C24: 해당 메뉴의 재료비 전부 합계 (⑤ 시트 SUMIF)
B25: 공급가액 | C25: 판매가 ÷ 부가세 계수 — 판매가가 부가세 포함이면 실제로 매장에 남는 금액
B26: 고정비 배분 | C26: 공급가액 × (배분대상 고정비 ÷ 월 매출 공급가액)
B27: 총원가 / 마진 | C27: 총원가 = 식재료 원가 + 고정비 배분, 마진 = 공급가액 − 총원가
B28: 원가율·마진율 | C28: 모두 판매가가 아니라 공급가액을 기준으로 계산합니다 (부가세는 매출이 아니므로)
A30: ▸ 꼭 알아두실 점
B31: 고정비 조정 | C31: 원본 고정비 목록의 「외상 매입금-식재료비(월 1,700만원)」는 메뉴별 식재료 원가에 이미 반영되어 있어 그대로 두면 이중 계산됩니다. 그래서 ③ 시트에서 「제외」로 두었습니다. 포함시키려면 「포함」으로 바꾸면 됩니다.
B32: 오류 방지 | C32: 모든 나눗셈은 분모가 0이면 0을 돌려주고, 모든 조회는 IFERROR로 감쌌습니다. 재료명을 바꾸거나 지워도 #DIV/0!·#N/A 가 뜨지 않습니다.
B33: 재료 추가 | C33: ⑤ 시트에서 줄을 복사해 메뉴명·재료명만 바꾸면 됩니다. 재료명은 ① 시트의 이름과 정확히 같아야 단가가 잡힙니다.
B34: 웹·모바일 | C34: 같은 데이터로 만든 웹 버전에서는 PC·휴대폰 모두에서 단가를 수정하고 이 엑셀을 다시 내려받을 수 있습니다.
A36: ▸ 오픈소스 라이선스 고지
B37: ExcelJS (MIT) | C37: Copyright (c) 2014-2019 Guyon Roche · https://github.com/exceljs/exceljs — 이 파일을 만드는 데 사용되었습니다. MIT 라이선스 전문은 함께 제공되는 THIRD-PARTY-NOTICES 문서를 참고하세요.

Sheet ⑥ 분석 대시보드
A1: ⑥ 분석 대시보드
A2: ① ~ ⑤ 시트의 값이 바뀌면 이 시트도 함께 자동으로 갱신됩니다.
B4: 전체 메뉴 | D4: 평균 식재료 원가율 | F4: 평균 총원가율 | H4: 평균 마진율 | J4: 고정비 배분율
B5: =COUNTA('④ 메뉴 원가표'!$C$6:$C$92) | D5: =IF('④ 메뉴 원가표'!$E$93>0,'④ 메뉴 원가표'!$F$93/'④ 메뉴 원가표'!$E$93,0) | F5: =IF('④ 메뉴 원가표'!$E$93>0,'④ 메뉴 원가표'!$I$93/'④ 메뉴 원가표'!$E$93,0) | H5: =IF('④ 메뉴 원가표'!$E$93>0,('④ 메뉴 원가표'!$E$93-'④ 메뉴 원가표'!$I$93)/'④ 메뉴 원가표'!$E$93,0) | J5: ='③ 고정비 설정'!$C$28
A7: ▸ 원가율 판정 현황
B8: ✅ 양호 | D8: =COUNTIF('④ 메뉴 원가표'!$M$6:$M$92,"*양호*") | E8: =IF(COUNTA('④ 메뉴 원가표'!$C$6:$C$92)>0,D8/COUNTA('④ 메뉴 원가표'!$C$6:$C$92),0)
B9: 🟡 주의 | D9: =COUNTIF('④ 메뉴 원가표'!$M$6:$M$92,"*주의*") | E9: =IF(COUNTA('④ 메뉴 원가표'!$C$6:$C$92)>0,D9/COUNTA('④ 메뉴 원가표'!$C$6:$C$92),0)
B10: 🔴 과다 | D10: =COUNTIF('④ 메뉴 원가표'!$M$6:$M$92,"*과다*") | E10: =IF(COUNTA('④ 메뉴 원가표'!$C$6:$C$92)>0,D10/COUNTA('④ 메뉴 원가표'!$C$6:$C$92),0)
B11: ⬜ 판매가 미입력 | D11: =COUNTIF('④ 메뉴 원가표'!$M$6:$M$92,"*판매가*") | E11: =IF(COUNTA('④ 메뉴 원가표'!$C$6:$C$92)>0,D11/COUNTA('④ 메뉴 원가표'!$C$6:$C$92),0)
A13: ▸ 카테고리별 원가 분석
B14: 카테고리 | C14: 메뉴수 | D14: 판매가 합계 | E14: 공급가액 | F14: 식재료원가 | G14: 원가율 | H14: 고정비배분 | I14: 총원가 | J14: 마진율
B15: 🍗 치킨 커리 | C15: =COUNTIF('④ 메뉴 원가표'!$B$6:$B$92,"🍗 치킨 커리") | D15: =SUMIF('④ 메뉴 원가표'!$B$6:$B$92,"🍗 치킨 커리",'④ 메뉴 원가표'!$D$6:$D$92) | E15: =SUMIF('④ 메뉴 원가표'!$B$6:$B$92,"🍗 치킨 커리",'④ 메뉴 원가표'!$E$6:$E$92) | F15: =SUMIF('④ 메뉴 원가표'!$B$6:$B$92,"🍗 치킨 커리",'④ 메뉴 원가표'!$F$6:$F$92) | G15: =IF(E15>0,F15/E15,"") | H15: =SUMIF('④ 메뉴 원가표'!$B$6:$B$92,"🍗 치킨 커리",'④ 메뉴 원가표'!$H$6:$H$92) | I15: =SUMIF('④ 메뉴 원가표'!$B$6:$B$92,"🍗 치킨 커리",'④ 메뉴 원가표'!$I$6:$I$92) | J15: =IF(E15>0,(E15-I15)/E15,"")
B16: 🐑 머턴 커리 | C16: =COUNTIF('④ 메뉴 원가표'!$B$6:$B$92,"🐑 머턴 커리") | D16: =SUMIF('④ 메뉴 원가표'!$B$6:$B$92,"🐑 머턴 커리",'④ 메뉴 원가표'!$D$6:$D$92) | E16: =SUMIF('④ 메뉴 원가표'!$B$6:$B$92,"🐑 머턴 커리",'④ 메뉴 원가표'!$E$6:$E$92) | F16: =SUMIF('④ 메뉴 원가표'!$B$6:$B$92,"🐑 머턴 커리",'④ 메뉴 원가표'!$F$6:$F$92) | G16: =IF(E16>0,F16/E16,"") | H16: =SUMIF('④ 메뉴 원가표'!$B$6:$B$92,"🐑 머턴 커리",'④ 메뉴 원가표'!$H$6:$H$92) | I16: =SUMIF('④ 메뉴 원가표'!$B$6:$B$92,"🐑 머턴 커리",'④ 메뉴 원가표'!$I$6:$I$92) | J16: =IF(E16>0,(E16-I16)/E16,"")
B17: 🦐 에그·해산물 | C17: =COUNTIF('④ 메뉴 원가표'!$B$6:$B$92,"🦐 에그·해산물") | D17: =SUMIF('④ 메뉴 원가표'!$B$6:$B$92,"🦐 에그·해산물",'④ 메뉴 원가표'!$D$6:$D$92) | E17: =SUMIF('④ 메뉴 원가표'!$B$6:$B$92,"🦐 에그·해산물",'④ 메뉴 원가표'!$E$6:$E$92) | F17: =SUMIF('④ 메뉴 원가표'!$B$6:$B$92,"🦐 에그·해산물",'④ 메뉴 원가표'!$F$6:$F$92) | G17: =IF(E17>0,F17/E17,"") | H17: =SUMIF('④ 메뉴 원가표'!$B$6:$B$92,"🦐 에그·해산물",'④ 메뉴 원가표'!$H$6:$H$92) | I17: =SUMIF('④ 메뉴 원가표'!$B$6:$B$92,"🦐 에그·해산물",'④ 메뉴 원가표'!$I$6:$I$92) | J17: =IF(E17>0,(E17-I17)/E17,"")
B18: 🥦 채식·달 커리 | C18: =COUNTIF('④ 메뉴 원가표'!$B$6:$B$92,"🥦 채식·달 커리") | D18: =SUMIF('④ 메뉴 원가표'!$B$6:$B$92,"🥦 채식·달 커리",'④ 메뉴 원가표'!$D$6:$D$92) | E18: =SUMIF('④ 메뉴 원가표'!$B$6:$B$92,"🥦 채식·달 커리",'④ 메뉴 원가표'!$E$6:$E$92) | F18: =SUMIF('④ 메뉴 원가표'!$B$6:$B$92,"🥦 채식·달 커리",'④ 메뉴 원가표'!$F$6:$F$92) | G18: =IF(E18>0,F18/E18,"") | H18: =SUMIF('④ 메뉴 원가표'!$B$6:$B$92,"🥦 채식·달 커리",'④ 메뉴 원가표'!$H$6:$H$92) | I18: =SUMIF('④ 메뉴 원가표'!$B$6:$B$92,"🥦 채식·달 커리",'④ 메뉴 원가표'!$I$6:$I$92) | J18: =IF(E18>0,(E18-I18)/E18,"")
B19: 🔥 탄두리·케밥 | C19: =COUNTIF('④ 메뉴 원가표'!$B$6:$B$92,"🔥 탄두리·케밥") | D19: =SUMIF('④ 메뉴 원가표'!$B$6:$B$92,"🔥 탄두리·케밥",'④ 메뉴 원가표'!$D$6:$D$92) | E19: =SUMIF('④ 메뉴 원가표'!$B$6:$B$92,"🔥 탄두리·케밥",'④ 메뉴 원가표'!$E$6:$E$92) | F19: =SUMIF('④ 메뉴 원가표'!$B$6:$B$92,"🔥 탄두리·케밥",'④ 메뉴 원가표'!$F$6:$F$92) | G19: =IF(E19>0,F19/E19,"") | H19: =SUMIF('④ 메뉴 원가표'!$B$6:$B$92,"🔥 탄두리·케밥",'④ 메뉴 원가표'!$H$6:$H$92) | I19: =SUMIF('④ 메뉴 원가표'!$B$6:$B$92,"🔥 탄두리·케밥",'④ 메뉴 원가표'!$I$6:$I$92) | J19: =IF(E19>0,(E19-I19)/E19,"")
B20: 🥟 스낵·사이드 | C20: =COUNTIF('④ 메뉴 원가표'!$B$6:$B$92,"🥟 스낵·사이드") | D20: =SUMIF('④ 메뉴 원가표'!$B$6:$B$92,"🥟 스낵·사이드",'④ 메뉴 원가표'!$D$6:$D$92) | E20: =SUMIF('④ 메뉴 원가표'!$B$6:$B$92,"🥟 스낵·사이드",'④ 메뉴 원가표'!$E$6:$E$92) | F20: =SUMIF('④ 메뉴 원가표'!$B$6:$B$92,"🥟 스낵·사이드",'④ 메뉴 원가표'!$F$6:$F$92) | G20: =IF(E20>0,F20/E20,"") | H20: =SUMIF('④ 메뉴 원가표'!$B$6:$B$92,"🥟 스낵·사이드",'④ 메뉴 원가표'!$H$6:$H$92) | I20: =SUMIF('④ 메뉴 원가표'!$B$6:$B$92,"🥟 스낵·사이드",'④ 메뉴 원가표'!$I$6:$I$92) | J20: =IF(E20>0,(E20-I20)/E20,"")
B21: 🍜 면류 | C21: =COUNTIF('④ 메뉴 원가표'!$B$6:$B$92,"🍜 면류") | D21: =SUMIF('④ 메뉴 원가표'!$B$6:$B$92,"🍜 면류",'④ 메뉴 원가표'!$D$6:$D$92) | E21: =SUMIF('④ 메뉴 원가표'!$B$6:$B$92,"🍜 면류",'④ 메뉴 원가표'!$E$6:$E$92) | F21: =SUMIF('④ 메뉴 원가표'!$B$6:$B$92,"🍜 면류",'④ 메뉴 원가표'!$F$6:$F$92) | G21: =IF(E21>0,F21/E21,"") | H21: =SUMIF('④ 메뉴 원가표'!$B$6:$B$92,"🍜 면류",'④ 메뉴 원가표'!$H$6:$H$92) | I21: =SUMIF('④ 메뉴 원가표'!$B$6:$B$92,"🍜 면류",'④ 메뉴 원가표'!$I$6:$I$92) | J21: =IF(E21>0,(E21-I21)/E21,"")
B22: 🍲 수프 | C22: =COUNTIF('④ 메뉴 원가표'!$B$6:$B$92,"🍲 수프") | D22: =SUMIF('④ 메뉴 원가표'!$B$6:$B$92,"🍲 수프",'④ 메뉴 원가표'!$D$6:$D$92) | E22: =SUMIF('④ 메뉴 원가표'!$B$6:$B$92,"🍲 수프",'④ 메뉴 원가표'!$E$6:$E$92) | F22: =SUMIF('④ 메뉴 원가표'!$B$6:$B$92,"🍲 수프",'④ 메뉴 원가표'!$F$6:$F$92) | G22: =IF(E22>0,F22/E22,"") | H22: =SUMIF('④ 메뉴 원가표'!$B$6:$B$92,"🍲 수프",'④ 메뉴 원가표'!$H$6:$H$92) | I22: =SUMIF('④ 메뉴 원가표'!$B$6:$B$92,"🍲 수프",'④ 메뉴 원가표'!$I$6:$I$92) | J22: =IF(E22>0,(E22-I22)/E22,"")
B23: 🫓 브레드 | C23: =COUNTIF('④ 메뉴 원가표'!$B$6:$B$92,"🫓 브레드") | D23: =SUMIF('④ 메뉴 원가표'!$B$6:$B$92,"🫓 브레드",'④ 메뉴 원가표'!$D$6:$D$92) | E23: =SUMIF('④ 메뉴 원가표'!$B$6:$B$92,"🫓 브레드",'④ 메뉴 원가표'!$E$6:$E$92) | F23: =SUMIF('④ 메뉴 원가표'!$B$6:$B$92,"🫓 브레드",'④ 메뉴 원가표'!$F$6:$F$92) | G23: =IF(E23>0,F23/E23,"") | H23: =SUMIF('④ 메뉴 원가표'!$B$6:$B$92,"🫓 브레드",'④ 메뉴 원가표'!$H$6:$H$92) | I23: =SUMIF('④ 메뉴 원가표'!$B$6:$B$92,"🫓 브레드",'④ 메뉴 원가표'!$I$6:$I$92) | J23: =IF(E23>0,(E23-I23)/E23,"")
B24: 🍚 밥류 | C24: =COUNTIF('④ 메뉴 원가표'!$B$6:$B$92,"🍚 밥류") | D24: =SUMIF('④ 메뉴 원가표'!$B$6:$B$92,"🍚 밥류",'④ 메뉴 원가표'!$D$6:$D$92) | E24: =SUMIF('④ 메뉴 원가표'!$B$6:$B$92,"🍚 밥류",'④ 메뉴 원가표'!$E$6:$E$92) | F24: =SUMIF('④ 메뉴 원가표'!$B$6:$B$92,"🍚 밥류",'④ 메뉴 원가표'!$F$6:$F$92) | G24: =IF(E24>0,F24/E24,"") | H24: =SUMIF('④ 메뉴 원가표'!$B$6:$B$92,"🍚 밥류",'④ 메뉴 원가표'!$H$6:$H$92) | I24: =SUMIF('④ 메뉴 원가표'!$B$6:$B$92,"🍚 밥류",'④ 메뉴 원가표'!$I$6:$I$92) | J24: =IF(E24>0,(E24-I24)/E24,"")
B25: 🥗 샐러드 | C25: =COUNTIF('④ 메뉴 원가표'!$B$6:$B$92,"🥗 샐러드") | D25: =SUMIF('④ 메뉴 원가표'!$B$6:$B$92,"🥗 샐러드",'④ 메뉴 원가표'!$D$6:$D$92) | E25: =SUMIF('④ 메뉴 원가표'!$B$6:$B$92,"🥗 샐러드",'④ 메뉴 원가표'!$E$6:$E$92) | F25: =SUMIF('④ 메뉴 원가표'!$B$6:$B$92,"🥗 샐러드",'④ 메뉴 원가표'!$F$6:$F$92) | G25: =IF(E25>0,F25/E25,"") | H25: =SUMIF('④ 메뉴 원가표'!$B$6:$B$92,"🥗 샐러드",'④ 메뉴 원가표'!$H$6:$H$92) | I25: =SUMIF('④ 메뉴 원가표'!$B$6:$B$92,"🥗 샐러드",'④ 메뉴 원가표'!$I$6:$I$92) | J25: =IF(E25>0,(E25-I25)/E25,"")
B26: 🍮 디저트 | C26: =COUNTIF('④ 메뉴 원가표'!$B$6:$B$92,"🍮 디저트") | D26: =SUMIF('④ 메뉴 원가표'!$B$6:$B$92,"🍮 디저트",'④ 메뉴 원가표'!$D$6:$D$92) | E26: =SUMIF('④ 메뉴 원가표'!$B$6:$B$92,"🍮 디저트",'④ 메뉴 원가표'!$E$6:$E$92) | F26: =SUMIF('④ 메뉴 원가표'!$B$6:$B$92,"🍮 디저트",'④ 메뉴 원가표'!$F$6:$F$92) | G26: =IF(E26>0,F26/E26,"") | H26: =SUMIF('④ 메뉴 원가표'!$B$6:$B$92,"🍮 디저트",'④ 메뉴 원가표'!$H$6:$H$92) | I26: =SUMIF('④ 메뉴 원가표'!$B$6:$B$92,"🍮 디저트",'④ 메뉴 원가표'!$I$6:$I$92) | J26: =IF(E26>0,(E26-I26)/E26,"")
B27: 🥤 음료 | C27: =COUNTIF('④ 메뉴 원가표'!$B$6:$B$92,"🥤 음료") | D27: =SUMIF('④ 메뉴 원가표'!$B$6:$B$92,"🥤 음료",'④ 메뉴 원가표'!$D$6:$D$92) | E27: =SUMIF('④ 메뉴 원가표'!$B$6:$B$92,"🥤 음료",'④ 메뉴 원가표'!$E$6:$E$92) | F27: =SUMIF('④ 메뉴 원가표'!$B$6:$B$92,"🥤 음료",'④ 메뉴 원가표'!$F$6:$F$92) | G27: =IF(E27>0,F27/E27,"") | H27: =SUMIF('④ 메뉴 원가표'!$B$6:$B$92,"🥤 음료",'④ 메뉴 원가표'!$H$6:$H$92) | I27: =SUMIF('④ 메뉴 원가표'!$B$6:$B$92,"🥤 음료",'④ 메뉴 원가표'!$I$6:$I$92) | J27: =IF(E27>0,(E27-I27)/E27,"")
B28: 🍽 세트메뉴 | C28: =COUNTIF('④ 메뉴 원가표'!$B$6:$B$92,"🍽 세트메뉴") | D28: =SUMIF('④ 메뉴 원가표'!$B$6:$B$92,"🍽 세트메뉴",'④ 메뉴 원가표'!$D$6:$D$92) | E28: =SUMIF('④ 메뉴 원가표'!$B$6:$B$92,"🍽 세트메뉴",'④ 메뉴 원가표'!$E$6:$E$92) | F28: =SUMIF('④ 메뉴 원가표'!$B$6:$B$92,"🍽 세트메뉴",'④ 메뉴 원가표'!$F$6:$F$92) | G28: =IF(E28>0,F28/E28,"") | H28: =SUMIF('④ 메뉴 원가표'!$B$6:$B$92,"🍽 세트메뉴",'④ 메뉴 원가표'!$H$6:$H$92) | I28: =SUMIF('④ 메뉴 원가표'!$B$6:$B$92,"🍽 세트메뉴",'④ 메뉴 원가표'!$I$6:$I$92) | J28: =IF(E28>0,(E28-I28)/E28,"")
A30: ▸ 식재료 원가율 상위 10 (개선 우선순위)
B31: 순위 | C31: 메뉴명 | D31: 판매가 | E31: 식재료원가 | F31: 원가율 | H31: 원가율 하위 10 (효자 메뉴)
B32: 1 | C32: =IFERROR(INDEX('④ 메뉴 원가표'!$C$6:$C$92,MATCH(LARGE('④ 메뉴 원가표'!$N$6:$N$92,1),'④ 메뉴 원가표'!$N$6:$N$92,0)),"") | D32: =IFERROR(INDEX('④ 메뉴 원가표'!$D$6:$D$92,MATCH(LARGE('④ 메뉴 원가표'!$N$6:$N$92,1),'④ 메뉴 원가표'!$N$6:$N$92,0)),"") | E32: =IFERROR(INDEX('④ 메뉴 원가표'!$F$6:$F$92,MATCH(LARGE('④ 메뉴 원가표'!$N$6:$N$92,1),'④ 메뉴 원가표'!$N$6:$N$92,0)),"") | F32: =IFERROR(INDEX('④ 메뉴 원가표'!$G$6:$G$92,MATCH(LARGE('④ 메뉴 원가표'!$N$6:$N$92,1),'④ 메뉴 원가표'!$N$6:$N$92,0)),"") | H32: 1 | I32: =IFERROR(INDEX('④ 메뉴 원가표'!$C$6:$C$92,MATCH(SMALL('④ 메뉴 원가표'!$N$6:$N$92,1),'④ 메뉴 원가표'!$N$6:$N$92,0)),"") | J32: =IFERROR(INDEX('④ 메뉴 원가표'!$G$6:$G$92,MATCH(SMALL('④ 메뉴 원가표'!$N$6:$N$92,1),'④ 메뉴 원가표'!$N$6:$N$92,0)),"")
B33: 2 | C33: =IFERROR(INDEX('④ 메뉴 원가표'!$C$6:$C$92,MATCH(LARGE('④ 메뉴 원가표'!$N$6:$N$92,2),'④ 메뉴 원가표'!$N$6:$N$92,0)),"") | D33: =IFERROR(INDEX('④ 메뉴 원가표'!$D$6:$D$92,MATCH(LARGE('④ 메뉴 원가표'!$N$6:$N$92,2),'④ 메뉴 원가표'!$N$6:$N$92,0)),"") | E33: =IFERROR(INDEX('④ 메뉴 원가표'!$F$6:$F$92,MATCH(LARGE('④ 메뉴 원가표'!$N$6:$N$92,2),'④ 메뉴 원가표'!$N$6:$N$92,0)),"") | F33: =IFERROR(INDEX('④ 메뉴 원가표'!$G$6:$G$92,MATCH(LARGE('④ 메뉴 원가표'!$N$6:$N$92,2),'④ 메뉴 원가표'!$N$6:$N$92,0)),"") | H33: 2 | I33: =IFERROR(INDEX('④ 메뉴 원가표'!$C$6:$C$92,MATCH(SMALL('④ 메뉴 원가표'!$N$6:$N$92,2),'④ 메뉴 원가표'!$N$6:$N$92,0)),"") | J33: =IFERROR(INDEX('④ 메뉴 원가표'!$G$6:$G$92,MATCH(SMALL('④ 메뉴 원가표'!$N$6:$N$92,2),'④ 메뉴 원가표'!$N$6:$N$92,0)),"")
B34: 3 | C34: =IFERROR(INDEX('④ 메뉴 원가표'!$C$6:$C$92,MATCH(LARGE('④ 메뉴 원가표'!$N$6:$N$92,3),'④ 메뉴 원가표'!$N$6:$N$92,0)),"") | D34: =IFERROR(INDEX('④ 메뉴 원가표'!$D$6:$D$92,MATCH(LARGE('④ 메뉴 원가표'!$N$6:$N$92,3),'④ 메뉴 원가표'!$N$6:$N$92,0)),"") | E34: =IFERROR(INDEX('④ 메뉴 원가표'!$F$6:$F$92,MATCH(LARGE('④ 메뉴 원가표'!$N$6:$N$92,3),'④ 메뉴 원가표'!$N$6:$N$92,0)),"") | F34: =IFERROR(INDEX('④ 메뉴 원가표'!$G$6:$G$92,MATCH(LARGE('④ 메뉴 원가표'!$N$6:$N$92,3),'④ 메뉴 원가표'!$N$6:$N$92,0)),"") | H34: 3 | I34: =IFERROR(INDEX('④ 메뉴 원가표'!$C$6:$C$92,MATCH(SMALL('④ 메뉴 원가표'!$N$6:$N$92,3),'④ 메뉴 원가표'!$N$6:$N$92,0)),"") | J34: =IFERROR(INDEX('④ 메뉴 원가표'!$G$6:$G$92,MATCH(SMALL('④ 메뉴 원가표'!$N$6:$N$92,3),'④ 메뉴 원가표'!$N$6:$N$92,0)),"")
B35: 4 | C35: =IFERROR(INDEX('④ 메뉴 원가표'!$C$6:$C$92,MATCH(LARGE('④ 메뉴 원가표'!$N$6:$N$92,4),'④ 메뉴 원가표'!$N$6:$N$92,0)),"") | D35: =IFERROR(INDEX('④ 메뉴 원가표'!$D$6:$D$92,MATCH(LARGE('④ 메뉴 원가표'!$N$6:$N$92,4),'④ 메뉴 원가표'!$N$6:$N$92,0)),"") | E35: =IFERROR(INDEX('④ 메뉴 원가표'!$F$6:$F$92,MATCH(LARGE('④ 메뉴 원가표'!$N$6:$N$92,4),'④ 메뉴 원가표'!$N$6:$N$92,0)),"") | F35: =IFERROR(INDEX('④ 메뉴 원가표'!$G$6:$G$92,MATCH(LARGE('④ 메뉴 원가표'!$N$6:$N$92,4),'④ 메뉴 원가표'!$N$6:$N$92,0)),"") | H35: 4 | I35: =IFERROR(INDEX('④ 메뉴 원가표'!$C$6:$C$92,MATCH(SMALL('④ 메뉴 원가표'!$N$6:$N$92,4),'④ 메뉴 원가표'!$N$6:$N$92,0)),"") | J35: =IFERROR(INDEX('④ 메뉴 원가표'!$G$6:$G$92,MATCH(SMALL('④ 메뉴 원가표'!$N$6:$N$92,4),'④ 메뉴 원가표'!$N$6:$N$92,0)),"")
B36: 5 | C36: =IFERROR(INDEX('④ 메뉴 원가표'!$C$6:$C$92,MATCH(LARGE('④ 메뉴 원가표'!$N$6:$N$92,5),'④ 메뉴 원가표'!$N$6:$N$92,0)),"") | D36: =IFERROR(INDEX('④ 메뉴 원가표'!$D$6:$D$92,MATCH(LARGE('④ 메뉴 원가표'!$N$6:$N$92,5),'④ 메뉴 원가표'!$N$6:$N$92,0)),"") | E36: =IFERROR(INDEX('④ 메뉴 원가표'!$F$6:$F$92,MATCH(LARGE('④ 메뉴 원가표'!$N$6:$N$92,5),'④ 메뉴 원가표'!$N$6:$N$92,0)),"") | F36: =IFERROR(INDEX('④ 메뉴 원가표'!$G$6:$G$92,MATCH(LARGE('④ 메뉴 원가표'!$N$6:$N$92,5),'④ 메뉴 원가표'!$N$6:$N$92,0)),"") | H36: 5 | I36: =IFERROR(INDEX('④ 메뉴 원가표'!$C$6:$C$92,MATCH(SMALL('④ 메뉴 원가표'!$N$6:$N$92,5),'④ 메뉴 원가표'!$N$6:$N$92,0)),"") | J36: =IFERROR(INDEX('④ 메뉴 원가표'!$G$6:$G$92,MATCH(SMALL('④ 메뉴 원가표'!$N$6:$N$92,5),'④ 메뉴 원가표'!$N$6:$N$92,0)),"")
B37: 6 | C37: =IFERROR(INDEX('④ 메뉴 원가표'!$C$6:$C$92,MATCH(LARGE('④ 메뉴 원가표'!$N$6:$N$92,6),'④ 메뉴 원가표'!$N$6:$N$92,0)),"") | D37: =IFERROR(INDEX('④ 메뉴 원가표'!$D$6:$D$92,MATCH(LARGE('④ 메뉴 원가표'!$N$6:$N$92,6),'④ 메뉴 원가표'!$N$6:$N$92,0)),"") | E37: =IFERROR(INDEX('④ 메뉴 원가표'!$F$6:$F$92,MATCH(LARGE('④ 메뉴 원가표'!$N$6:$N$92,6),'④ 메뉴 원가표'!$N$6:$N$92,0)),"") | F37: =IFERROR(INDEX('④ 메뉴 원가표'!$G$6:$G$92,MATCH(LARGE('④ 메뉴 원가표'!$N$6:$N$92,6),'④ 메뉴 원가표'!$N$6:$N$92,0)),"") | H37: 6 | I37: =IFERROR(INDEX('④ 메뉴 원가표'!$C$6:$C$92,MATCH(SMALL('④ 메뉴 원가표'!$N$6:$N$92,6),'④ 메뉴 원가표'!$N$6:$N$92,0)),"") | J37: =IFERROR(INDEX('④ 메뉴 원가표'!$G$6:$G$92,MATCH(SMALL('④ 메뉴 원가표'!$N$6:$N$92,6),'④ 메뉴 원가표'!$N$6:$N$92,0)),"")
B38: 7 | C38: =IFERROR(INDEX('④ 메뉴 원가표'!$C$6:$C$92,MATCH(LARGE('④ 메뉴 원가표'!$N$6:$N$92,7),'④ 메뉴 원가표'!$N$6:$N$92,0)),"") | D38: =IFERROR(INDEX('④ 메뉴 원가표'!$D$6:$D$92,MATCH(LARGE('④ 메뉴 원가표'!$N$6:$N$92,7),'④ 메뉴 원가표'!$N$6:$N$92,0)),"") | E38: =IFERROR(INDEX('④ 메뉴 원가표'!$F$6:$F$92,MATCH(LARGE('④ 메뉴 원가표'!$N$6:$N$92,7),'④ 메뉴 원가표'!$N$6:$N$92,0)),"") | F38: =IFERROR(INDEX('④ 메뉴 원가표'!$G$6:$G$92,MATCH(LARGE('④ 메뉴 원가표'!$N$6:$N$92,7),'④ 메뉴 원가표'!$N$6:$N$92,0)),"") | H38: 7 | I38: =IFERROR(INDEX('④ 메뉴 원가표'!$C$6:$C$92,MATCH(SMALL('④ 메뉴 원가표'!$N$6:$N$92,7),'④ 메뉴 원가표'!$N$6:$N$92,0)),"") | J38: =IFERROR(INDEX('④ 메뉴 원가표'!$G$6:$G$92,MATCH(SMALL('④ 메뉴 원가표'!$N$6:$N$92,7),'④ 메뉴 원가표'!$N$6:$N$92,0)),"")
B39: 8 | C39: =IFERROR(INDEX('④ 메뉴 원가표'!$C$6:$C$92,MATCH(LARGE('④ 메뉴 원가표'!$N$6:$N$92,8),'④ 메뉴 원가표'!$N$6:$N$92,0)),"") | D39: =IFERROR(INDEX('④ 메뉴 원가표'!$D$6:$D$92,MATCH(LARGE('④ 메뉴 원가표'!$N$6:$N$92,8),'④ 메뉴 원가표'!$N$6:$N$92,0)),"") | E39: =IFERROR(INDEX('④ 메뉴 원가표'!$F$6:$F$92,MATCH(LARGE('④ 메뉴 원가표'!$N$6:$N$92,8),'④ 메뉴 원가표'!$N$6:$N$92,0)),"") | F39: =IFERROR(INDEX('④ 메뉴 원가표'!$G$6:$G$92,MATCH(LARGE('④ 메뉴 원가표'!$N$6:$N$92,8),'④ 메뉴 원가표'!$N$6:$N$92,0)),"") | H39: 8 | I39: =IFERROR(INDEX('④ 메뉴 원가표'!$C$6:$C$92,MATCH(SMALL('④ 메뉴 원가표'!$N$6:$N$92,8),'④ 메뉴 원가표'!$N$6:$N$92,0)),"") | J39: =IFERROR(INDEX('④ 메뉴 원가표'!$G$6:$G$92,MATCH(SMALL('④ 메뉴 원가표'!$N$6:$N$92,8),'④ 메뉴 원가표'!$N$6:$N$92,0)),"")
B40: 9 | C40: =IFERROR(INDEX('④ 메뉴 원가표'!$C$6:$C$92,MATCH(LARGE('④ 메뉴 원가표'!$N$6:$N$92,9),'④ 메뉴 원가표'!$N$6:$N$92,0)),"") | D40: =IFERROR(INDEX('④ 메뉴 원가표'!$D$6:$D$92,MATCH(LARGE('④ 메뉴 원가표'!$N$6:$N$92,9),'④ 메뉴 원가표'!$N$6:$N$92,0)),"") | E40: =IFERROR(INDEX('④ 메뉴 원가표'!$F$6:$F$92,MATCH(LARGE('④ 메뉴 원가표'!$N$6:$N$92,9),'④ 메뉴 원가표'!$N$6:$N$92,0)),"") | F40: =IFERROR(INDEX('④ 메뉴 원가표'!$G$6:$G$92,MATCH(LARGE('④ 메뉴 원가표'!$N$6:$N$92,9),'④ 메뉴 원가표'!$N$6:$N$92,0)),"") | H40: 9 | I40: =IFERROR(INDEX('④ 메뉴 원가표'!$C$6:$C$92,MATCH(SMALL('④ 메뉴 원가표'!$N$6:$N$92,9),'④ 메뉴 원가표'!$N$6:$N$92,0)),"") | J40: =IFERROR(INDEX('④ 메뉴 원가표'!$G$6:$G$92,MATCH(SMALL('④ 메뉴 원가표'!$N$6:$N$92,9),'④ 메뉴 원가표'!$N$6:$N$92,0)),"")
B41: 10 | C41: =IFERROR(INDEX('④ 메뉴 원가표'!$C$6:$C$92,MATCH(LARGE('④ 메뉴 원가표'!$N$6:$N$92,10),'④ 메뉴 원가표'!$N$6:$N$92,0)),"") | D41: =IFERROR(INDEX('④ 메뉴 원가표'!$D$6:$D$92,MATCH(LARGE('④ 메뉴 원가표'!$N$6:$N$92,10),'④ 메뉴 원가표'!$N$6:$N$92,0)),"") | E41: =IFERROR(INDEX('④ 메뉴 원가표'!$F$6:$F$92,MATCH(LARGE('④ 메뉴 원가표'!$N$6:$N$92,10),'④ 메뉴 원가표'!$N$6:$N$92,0)),"") | F41: =IFERROR(INDEX('④ 메뉴 원가표'!$G$6:$G$92,MATCH(LARGE('④ 메뉴 원가표'!$N$6:$N$92,10),'④ 메뉴 원가표'!$N$6:$N$92,0)),"") | H41: 10 | I41: =IFERROR(INDEX('④ 메뉴 원가표'!$C$6:$C$92,MATCH(SMALL('④ 메뉴 원가표'!$N$6:$N$92,10),'④ 메뉴 원가표'!$N$6:$N$92,0)),"") | J41: =IFERROR(INDEX('④ 메뉴 원가표'!$G$6:$G$92,MATCH(SMALL('④ 메뉴 원가표'!$N$6:$N$92,10),'④ 메뉴 원가표'!$N$6:$N$92,0)),"")

Sheet ④ 메뉴 원가표
A1: ④ 메뉴 원가표
A2: 메뉴 87개 전체. 판매가(노란 셀)만 고치면 원가율·마진이 즉시 다시 계산됩니다.
A3: 💡 공급가액 = 판매가 ÷ 부가세 계수 (③ 시트). 원가율·마진은 모두 공급가액 기준입니다. 고정비 배분 = 공급가액 × 고정비 배분율. 총원가 = 식재료원가 + 고정비 배분.
A5: No. | B5: 카테고리 | C5: 메뉴명 | D5: 판매가(원) | E5: 공급가액 | F5: 식재료원가 | G5: 식재료 원가율 | H5: 고정비배분 | I5: 총원가 | J5: 총원가율 | K5: 마진(원) | L5: 마진율 | M5: 판정 | N5: 정렬키
A6: 1 | B6: 🍗 치킨 커리 | C6: 버터 치킨 | D6: 15000 | E6: =ROUND($D6/'③ 고정비 설정'!$C$25,0) | F6: =ROUND(SUMIF('⑤ 레시피 상세'!$B$6:$B$593,$C6,'⑤ 레시피 상세'!$K$6:$K$593),1) | G6: =IF($E6>0,$F6/$E6,"") | H6: =ROUND($E6*'③ 고정비 설정'!$C$28,0) | I6: =ROUND($F6+$H6,0) | J6: =IF($E6>0,$I6/$E6,"") | K6: =IF($E6>0,$E6-$I6,"") | L6: =IF($E6>0,$K6/$E6,"") | M6: =IF($D6<=0,"⬜ 판매가 입력",IF($F6<=0,"⬜ 재료 확인",IF($G6<='③ 고정비 설정'!$C$29,"✅ 양호",IF($G6<='③ 고정비 설정'!$C$30,"🟡 주의","🔴 과다")))) | N6: =IF($D6>0,$G6+ROW()/1000000,"")
A7: 2 | B7: 🍗 치킨 커리 | C7: 베이비 커리 | D7: 13000 | E7: =ROUND($D7/'③ 고정비 설정'!$C$25,0) | F7: =ROUND(SUMIF('⑤ 레시피 상세'!$B$6:$B$593,$C7,'⑤ 레시피 상세'!$K$6:$K$593),1) | G7: =IF($E7>0,$F7/$E7,"") | H7: =ROUND($E7*'③ 고정비 설정'!$C$28,0) | I7: =ROUND($F7+$H7,0) | J7: =IF($E7>0,$I7/$E7,"") | K7: =IF($E7>0,$E7-$I7,"") | L7: =IF($E7>0,$K7/$E7,"") | M7: =IF($D7<=0,"⬜ 판매가 입력",IF($F7<=0,"⬜ 재료 확인",IF($G7<='③ 고정비 설정'!$C$29,"✅ 양호",IF($G7<='③ 고정비 설정'!$C$30,"🟡 주의","🔴 과다")))) | N7: =IF($D7>0,$G7+ROW()/1000000,"")
A8: 3 | B8: 🍗 치킨 커리 | C8: 스페셜 커리치킨 | D8: 14000 | E8: =ROUND($D8/'③ 고정비 설정'!$C$25,0) | F8: =ROUND(SUMIF('⑤ 레시피 상세'!$B$6:$B$593,$C8,'⑤ 레시피 상세'!$K$6:$K$593),1) | G8: =IF($E8>0,$F8/$E8,"") | H8: =ROUND($E8*'③ 고정비 설정'!$C$28,0) | I8: =ROUND($F8+$H8,0) | J8: =IF($E8>0,$I8/$E8,"") | K8: =IF($E8>0,$E8-$I8,"") | L8: =IF($E8>0,$K8/$E8,"") | M8: =IF($D8<=0,"⬜ 판매가 입력",IF($F8<=0,"⬜ 재료 확인",IF($G8<='③ 고정비 설정'!$C$29,"✅ 양호",IF($G8<='③ 고정비 설정'!$C$30,"🟡 주의","🔴 과다")))) | N8: =IF($D8>0,$G8+ROW()/1000000,"")
A9: 4 | B9: 🍗 치킨 커리 | C9: 진저 치킨 | D9: 12000 | E9: =ROUND($D9/'③ 고정비 설정'!$C$25,0) | F9: =ROUND(SUMIF('⑤ 레시피 상세'!$B$6:$B$593,$C9,'⑤ 레시피 상세'!$K$6:$K$593),1) | G9: =IF($E9>0,$F9/$E9,"") | H9: =ROUND($E9*'③ 고정비 설정'!$C$28,0) | I9: =ROUND($F9+$H9,0) | J9: =IF($E9>0,$I9/$E9,"") | K9: =IF($E9>0,$E9-$I9,"") | L9: =IF($E9>0,$K9/$E9,"") | M9: =IF($D9<=0,"⬜ 판매가 입력",IF($F9<=0,"⬜ 재료 확인",IF($G9<='③ 고정비 설정'!$C$29,"✅ 양호",IF($G9<='③ 고정비 설정'!$C$30,"🟡 주의","🔴 과다")))) | N9: =IF($D9>0,$G9+ROW()/1000000,"")
A10: 5 | B10: 🍗 치킨 커리 | C10: 치킨 마살라 | D10: 12000 | E10: =ROUND($D10/'③ 고정비 설정'!$C$25,0) | F10: =ROUND(SUMIF('⑤ 레시피 상세'!$B$6:$B$593,$C10,'⑤ 레시피 상세'!$K$6:$K$593),1) | G10: =IF($E10>0,$F10/$E10,"") | H10: =ROUND($E10*'③ 고정비 설정'!$C$28,0) | I10: =ROUND($F10+$H10,0) | J10: =IF($E10>0,$I10/$E10,"") | K10: =IF($E10>0,$E10-$I10,"") | L10: =IF($E10>0,$K10/$E10,"") | M10: =IF($D10<=0,"⬜ 판매가 입력",IF($F10<=0,"⬜ 재료 확인",IF($G10<='③ 고정비 설정'!$C$29,"✅ 양호",IF($G10<='③ 고정비 설정'!$C$30,"🟡 주의","🔴 과다")))) | N10: =IF($D10>0,$G10+ROW()/1000000,"")
A11: 6 | B11: 🍗 치킨 커리 | C11: 치킨 빈달루 | D11: 14000 | E11: =ROUND($D11/'③ 고정비 설정'!$C$25,0) | F11: =ROUND(SUMIF('⑤ 레시피 상세'!$B$6:$B$593,$C11,'⑤ 레시피 상세'!$K$6:$K$593),1) | G11: =IF($E11>0,$F11/$E11,"") | H11: =ROUND($E11*'③ 고정비 설정'!$C$28,0) | I11: =ROUND($F11+$H11,0) | J11: =IF($E11>0,$I11/$E11,"") | K11: =IF($E11>0,$E11-$I11,"") | L11: =IF($E11>0,$K11/$E11,"") | M11: =IF($D11<=0,"⬜ 판매가 입력",IF($F11<=0,"⬜ 재료 확인",IF($G11<='③ 고정비 설정'!$C$29,"✅ 양호",IF($G11<='③ 고정비 설정'!$C$30,"🟡 주의","🔴 과다")))) | N11: =IF($D11>0,$G11+ROW()/1000000,"")
A12: 7 | B12: 🍗 치킨 커리 | C12: 치킨 커리 | D12: 12000 | E12: =ROUND($D12/'③ 고정비 설정'!$C$25,0) | F12: =ROUND(SUMIF('⑤ 레시피 상세'!$B$6:$B$593,$C12,'⑤ 레시피 상세'!$K$6:$K$593),1) | G12: =IF($E12>0,$F12/$E12,"") | H12: =ROUND($E12*'③ 고정비 설정'!$C$28,0) | I12: =ROUND($F12+$H12,0) | J12: =IF($E12>0,$I12/$E12,"") | K12: =IF($E12>0,$E12-$I12,"") | L12: =IF($E12>0,$K12/$E12,"") | M12: =IF($D12<=0,"⬜ 판매가 입력",IF($F12<=0,"⬜ 재료 확인",IF($G12<='③ 고정비 설정'!$C$29,"✅ 양호",IF($G12<='③ 고정비 설정'!$C$30,"🟡 주의","🔴 과다")))) | N12: =IF($D12>0,$G12+ROW()/1000000,"")
A13: 8 | B13: 🍗 치킨 커리 | C13: 치킨 코르마 | D13: 12000 | E13: =ROUND($D13/'③ 고정비 설정'!$C$25,0) | F13: =ROUND(SUMIF('⑤ 레시피 상세'!$B$6:$B$593,$C13,'⑤ 레시피 상세'!$K$6:$K$593),1) | G13: =IF($E13>0,$F13/$E13,"") | H13: =ROUND($E13*'③ 고정비 설정'!$C$28,0) | I13: =ROUND($F13+$H13,0) | J13: =IF($E13>0,$I13/$E13,"") | K13: =IF($E13>0,$E13-$I13,"") | L13: =IF($E13>0,$K13/$E13,"") | M13: =IF($D13<=0,"⬜ 판매가 입력",IF($F13<=0,"⬜ 재료 확인",IF($G13<='③ 고정비 설정'!$C$29,"✅ 양호",IF($G13<='③ 고정비 설정'!$C$30,"🟡 주의","🔴 과다")))) | N13: =IF($D13>0,$G13+ROW()/1000000,"")
A14: 9 | B14: 🍗 치킨 커리 | C14: 치킨 티카 마살라 | D14: 13000 | E14: =ROUND($D14/'③ 고정비 설정'!$C$25,0) | F14: =ROUND(SUMIF('⑤ 레시피 상세'!$B$6:$B$593,$C14,'⑤ 레시피 상세'!$K$6:$K$593),1) | G14: =IF($E14>0,$F14/$E14,"") | H14: =ROUND($E14*'③ 고정비 설정'!$C$28,0) | I14: =ROUND($F14+$H14,0) | J14: =IF($E14>0,$I14/$E14,"") | K14: =IF($E14>0,$E14-$I14,"") | L14: =IF($E14>0,$K14/$E14,"") | M14: =IF($D14<=0,"⬜ 판매가 입력",IF($F14<=0,"⬜ 재료 확인",IF($G14<='③ 고정비 설정'!$C$29,"✅ 양호",IF($G14<='③ 고정비 설정'!$C$30,"🟡 주의","🔴 과다")))) | N14: =IF($D14>0,$G14+ROW()/1000000,"")
A15: 10 | B15: 🍗 치킨 커리 | C15: 치킨머커니 | D15: 13000 | E15: =ROUND($D15/'③ 고정비 설정'!$C$25,0) | F15: =ROUND(SUMIF('⑤ 레시피 상세'!$B$6:$B$593,$C15,'⑤ 레시피 상세'!$K$6:$K$593),1) | G15: =IF($E15>0,$F15/$E15,"") | H15: =ROUND($E15*'③ 고정비 설정'!$C$28,0) | I15: =ROUND($F15+$H15,0) | J15: =IF($E15>0,$I15/$E15,"") | K15: =IF($E15>0,$E15-$I15,"") | L15: =IF($E15>0,$K15/$E15,"") | M15: =IF($D15<=0,"⬜ 판매가 입력",IF($F15<=0,"⬜ 재료 확인",IF($G15<='③ 고정비 설정'!$C$29,"✅ 양호",IF($G15<='③ 고정비 설정'!$C$30,"🟡 주의","🔴 과다")))) | N15: =IF($D15>0,$G15+ROW()/1000000,"")
A16: 11 | B16: 🍗 치킨 커리 | C16: 커다이 치킨 | D16: 13000 | E16: =ROUND($D16/'③ 고정비 설정'!$C$25,0) | F16: =ROUND(SUMIF('⑤ 레시피 상세'!$B$6:$B$593,$C16,'⑤ 레시피 상세'!$K$6:$K$593),1) | G16: =IF($E16>0,$F16/$E16,"") | H16: =ROUND($E16*'③ 고정비 설정'!$C$28,0) | I16: =ROUND($F16+$H16,0) | J16: =IF($E16>0,$I16/$E16,"") | K16: =IF($E16>0,$E16-$I16,"") | L16: =IF($E16>0,$K16/$E16,"") | M16: =IF($D16<=0,"⬜ 판매가 입력",IF($F16<=0,"⬜ 재료 확인",IF($G16<='③ 고정비 설정'!$C$29,"✅ 양호",IF($G16<='③ 고정비 설정'!$C$30,"🟡 주의","🔴 과다")))) | N16: =IF($D16>0,$G16+ROW()/1000000,"")
A17: 12 | B17: 🐑 머턴 커리 | C17: 머턴 도 피아자 | D17: 14000 | E17: =ROUND($D17/'③ 고정비 설정'!$C$25,0) | F17: =ROUND(SUMIF('⑤ 레시피 상세'!$B$6:$B$593,$C17,'⑤ 레시피 상세'!$K$6:$K$593),1) | G17: =IF($E17>0,$F17/$E17,"") | H17: =ROUND($E17*'③ 고정비 설정'!$C$28,0) | I17: =ROUND($F17+$H17,0) | J17: =IF($E17>0,$I17/$E17,"") | K17: =IF($E17>0,$E17-$I17,"") | L17: =IF($E17>0,$K17/$E17,"") | M17: =IF($D17<=0,"⬜ 판매가 입력",IF($F17<=0,"⬜ 재료 확인",IF($G17<='③ 고정비 설정'!$C$29,"✅ 양호",IF($G17<='③ 고정비 설정'!$C$30,"🟡 주의","🔴 과다")))) | N17: =IF($D17>0,$G17+ROW()/1000000,"")
... A89: 84 | B89: 🥤 음료 | C89: 플레인 라씨 | D89: 3500 | E89: =ROUND($D89/'③ 고정비 설정'!$C$25,0) | F89: =ROUND(SUMIF('⑤ 레시피 상세'!$B$6:$B$593,$C89,'⑤ 레시피 상세'!$K$6:$K$593),1) | G89: =IF($E89>0,$F89/$E89,"") | H89: =ROUND($E89*'③ 고정비 설정'!$C$28,0) | I89: =ROUND($F89+$H89,0) | J89: =IF($E89>0,$I89/$E89,"") | K89: =IF($E89>0,$E89-$I89,"") | L89: =IF($E89>0,$K89/$E89,"") | M89: =IF($D89<=0,"⬜ 판매가 입력",IF($F89<=0,"⬜ 재료 확인",IF($G89<='③ 고정비 설정'!$C$29,"✅ 양호",IF($G89<='③ 고정비 설정'!$C$30,"🟡 주의","🔴 과다")))) | N89: =IF($D89>0,$G89+ROW()/1000000,"")
A90: 85 | B90: 🍽 세트메뉴 | C90: A set (2인) | D90: 32000 | E90: =ROUND($D90/'③ 고정비 설정'!$C$25,0) | F90: =ROUND(SUMIF('⑤ 레시피 상세'!$B$594:$B$612,$C90,'⑤ 레시피 상세'!$K$594:$K$612),1) | G90: =IF($E90>0,$F90/$E90,"") | H90: =ROUND($E90*'③ 고정비 설정'!$C$28,0) | I90: =ROUND($F90+$H90,0) | J90: =IF($E90>0,$I90/$E90,"") | K90: =IF($E90>0,$E90-$I90,"") | L90: =IF($E90>0,$K90/$E90,"") | M90: =IF($D90<=0,"⬜ 판매가 입력",IF($F90<=0,"⬜ 재료 확인",IF($G90<='③ 고정비 설정'!$C$29,"✅ 양호",IF($G90<='③ 고정비 설정'!$C$30,"🟡 주의","🔴 과다")))) | N90: =IF($D90>0,$G90+ROW()/1000000,"")
A91: 86 | B91: 🍽 세트메뉴 | C91: B set (3인) | D91: 57000 | E91: =ROUND($D91/'③ 고정비 설정'!$C$25,0) | F91: =ROUND(SUMIF('⑤ 레시피 상세'!$B$594:$B$612,$C91,'⑤ 레시피 상세'!$K$594:$K$612),1) | G91: =IF($E91>0,$F91/$E91,"") | H91: =ROUND($E91*'③ 고정비 설정'!$C$28,0) | I91: =ROUND($F91+$H91,0) | J91: =IF($E91>0,$I91/$E91,"") | K91: =IF($E91>0,$E91-$I91,"") | L91: =IF($E91>0,$K91/$E91,"") | M91: =IF($D91<=0,"⬜ 판매가 입력",IF($F91<=0,"⬜ 재료 확인",IF($G91<='③ 고정비 설정'!$C$29,"✅ 양호",IF($G91<='③ 고정비 설정'!$C$30,"🟡 주의","🔴 과다")))) | N91: =IF($D91>0,$G91+ROW()/1000000,"")
A92: 87 | B92: 🍽 세트메뉴 | C92: C set (3인) | D92: 71000 | E92: =ROUND($D92/'③ 고정비 설정'!$C$25,0) | F92: =ROUND(SUMIF('⑤ 레시피 상세'!$B$594:$B$612,$C92,'⑤ 레시피 상세'!$K$594:$K$612),1) | G92: =IF($E92>0,$F92/$E92,"") | H92: =ROUND($E92*'③ 고정비 설정'!$C$28,0) | I92: =ROUND($F92+$H92,0) | J92: =IF($E92>0,$I92/$E92,"") | K92: =IF($E92>0,$E92-$I92,"") | L92: =IF($E92>0,$K92/$E92,"") | M92: =IF($D92<=0,"⬜ 판매가 입력",IF($F92<=0,"⬜ 재료 확인",IF($G92<='③ 고정비 설정'!$C$29,"✅ 양호",IF($G92<='③ 고정비 설정'!$C$30,"🟡 주의","🔴 과다")))) | N92: =IF($D92>0,$G92+ROW()/1000000,"")
A93: 합 계 / 가중평균 | D93: =SUM(D6:D92) | E93: =SUM(E6:E92) | F93: =SUM(F6:F92) | G93: =IF(E93>0,F93/E93,"") | H93: =SUM(H6:H92) | I93: =SUM(I6:I92) | J93: =IF(E93>0,I93/E93,"") | K93: =IF(E93>0,E93-I93,"") | L93: =IF(E93>0,K93/E93,"") | M93: ="✅"&COUNTIF(M6:M92,"*양호*")&" 🟡"&COUNTIF(M6:M92,"*주의*")&" 🔴"&COUNTIF(M6:M92,"*과다*")

Sheet ⑤ 레시피 상세
A1: ⑤ 레시피 상세 원가
A2: 레시피북과 동일한 재료·사용량. 한 줄 = 재료 1개. 사용량·수율만 고치면 메뉴 원가가 자동 갱신됩니다.
A3: 💡 재료비 = 사용량 ÷ 수율 × g당 단가. 구분이 「메뉴」인 줄(세트메뉴 구성품)은 = 수량 × 해당 단품의 식재료 원가. 「무료」는 수돗물 등 원가 0.
A5: 카테고리 | B5: 메뉴명 | C5: 순번 | D5: 구분 | E5: 재료 / 구성 | F5: 레시피북 표기 | G5: 사용량 | H5: 단위 | I5: 수율 | J5: g당 단가(원) | K5: 재료비(원) | L5: 비고
A6: 🍗 치킨 커리 | B6: 버터 치킨 | C6: 1 | D6: 식재료 | E6: 닭 09호 | F6: 닭 (09호) | G6: 100 | H6: g | I6: 1 | J6: =IF($D6="무료",0,IF($D6="메뉴",0,IF($D6="프렙",IFERROR(VLOOKUP($E6,'② 프렙 원가'!$B$6:$F$16,5,FALSE),0),IFERROR(VLOOKUP($E6,'① 식재료 단가'!$B$6:$G$123,6,FALSE),0)))) | K6: =IF($D6="메뉴",ROUND($G6*$J6,1),IF($I6>0,ROUND($G6/$I6*$J6,1),0)) | L6: 탄두리로 미리 구운 것
A7: 🍗 치킨 커리 | B7: 버터 치킨 | C7: 2 | D7: 프렙 | E7: 커리 그레이비 소스 | G7: 200 | H7: g | I7: 1 | J7: =IF($D7="무료",0,IF($D7="메뉴",0,IF($D7="프렙",IFERROR(VLOOKUP($E7,'② 프렙 원가'!$B$6:$F$16,5,FALSE),0),IFERROR(VLOOKUP($E7,'① 식재료 단가'!$B$6:$G$123,6,FALSE),0)))) | K7: =IF($D7="메뉴",ROUND($G7*$J7,1),IF($I7>0,ROUND($G7/$I7*$J7,1),0)) | L7: 사전 조리된 베이스
A8: 🍗 치킨 커리 | B8: 버터 치킨 | C8: 3 | D8: 식재료 | E8: ASEEL PURE GHEE | F8: ASEEL PURE GHEE (버터) | G8: 10 | H8: g | I8: 1 | J8: =IF($D8="무료",0,IF($D8="메뉴",0,IF($D8="프렙",IFERROR(VLOOKUP($E8,'② 프렙 원가'!$B$6:$F$16,5,FALSE),0),IFERROR(VLOOKUP($E8,'① 식재료 단가'!$B$6:$G$123,6,FALSE),0)))) | K8: =IF($D8="메뉴",ROUND($G8*$J8,1),IF($I8>0,ROUND($G8/$I8*$J8,1),0)) | L8: 풍미용
A9: 🍗 치킨 커리 | B9: 버터 치킨 | C9: 4 | D9: 식재료 | E9: 데어리쿠킹크림 | G9: 30 | H9: g | I9: 1 | J9: =IF($D9="무료",0,IF($D9="메뉴",0,IF($D9="프렙",IFERROR(VLOOKUP($E9,'② 프렙 원가'!$B$6:$F$16,5,FALSE),0),IFERROR(VLOOKUP($E9,'① 식재료 단가'!$B$6:$G$123,6,FALSE),0)))) | K9: =IF($D9="메뉴",ROUND($G9*$J9,1),IF($I9>0,ROUND($G9/$I9*$J9,1),0))
A10: 🍗 치킨 커리 | B10: 버터 치킨 | C10: 5 | D10: 식재료 | E10: 꽃소금 | G10: 5 | H10: g | I10: 1 | J10: =IF($D10="무료",0,IF($D10="메뉴",0,IF($D10="프렙",IFERROR(VLOOKUP($E10,'② 프렙 원가'!$B$6:$F$16,5,FALSE),0),IFERROR(VLOOKUP($E10,'① 식재료 단가'!$B$6:$G$123,6,FALSE),0)))) | K10: =IF($D10="메뉴",ROUND($G10*$J10,1),IF($I10>0,ROUND($G10/$I10*$J10,1),0))
A11: 🍗 치킨 커리 | B11: 버터 치킨 | C11: 6 | D11: 식재료 | E11: 설탕 | G11: 3 | H11: g | I11: 1 | J11: =IF($D11="무료",0,IF($D11="메뉴",0,IF($D11="프렙",IFERROR(VLOOKUP($E11,'② 프렙 원가'!$B$6:$F$16,5,FALSE),0),IFERROR(VLOOKUP($E11,'① 식재료 단가'!$B$6:$G$123,6,FALSE),0)))) | K11: =IF($D11="메뉴",ROUND($G11*$J11,1),IF($I11>0,ROUND($G11/$I11*$J11,1),0)) | L11: 단맛 밸런스
A12: 🍗 치킨 커리 | B12: 버터 치킨 | C12: 7 | D12: 식재료 | E12: 부라보 | F12: 버터 | G12: 5 | H12: g | I12: 1 | J12: =IF($D12="무료",0,IF($D12="메뉴",0,IF($D12="프렙",IFERROR(VLOOKUP($E12,'② 프렙 원가'!$B$6:$F$16,5,FALSE),0),IFERROR(VLOOKUP($E12,'① 식재료 단가'!$B$6:$G$123,6,FALSE),0)))) | K12: =IF($D12="메뉴",ROUND($G12*$J12,1),IF($I12>0,ROUND($G12/$I12*$J12,1),0)) | L12: 큐브 조각
A13: 🍗 치킨 커리 | B13: 베이비 커리 | C13: 1 | D13: 식재료 | E13: 가슴 대한 | F13: 닭가슴살 (정육) | G13: 35 | H13: g | I13: 1 | J13: =IF($D13="무료",0,IF($D13="메뉴",0,IF($D13="프렙",IFERROR(VLOOKUP($E13,'② 프렙 원가'!$B$6:$F$16,5,FALSE),0),IFERROR(VLOOKUP($E13,'① 식재료 단가'!$B$6:$G$123,6,FALSE),0)))) | K13: =IF($D13="메뉴",ROUND($G13*$J13,1),IF($I13>0,ROUND($G13/$I13*$J13,1),0)) | L13: 작게 썰기
A14: 🍗 치킨 커리 | B14: 베이비 커리 | C14: 2 | D14: 프렙 | E14: 베이비커리 | F14: 베이비커리 소스 | G14: 170 | H14: g | I14: 1 | J14: =IF($D14="무료",0,IF($D14="메뉴",0,IF($D14="프렙",IFERROR(VLOOKUP($E14,'② 프렙 원가'!$B$6:$F$16,5,FALSE),0),IFERROR(VLOOKUP($E14,'① 식재료 단가'!$B$6:$G$123,6,FALSE),0)))) | K14: =IF($D14="메뉴",ROUND($G14*$J14,1),IF($I14>0,ROUND($G14/$I14*$J14,1),0)) | L14: 코코넛-캐슈 베이스
A15: 🍗 치킨 커리 | B15: 베이비 커리 | C15: 3 | D15: 식재료 | E15: 데어리쿠킹크림 | G15: 25 | H15: g | I15: 1 | J15: =IF($D15="무료",0,IF($D15="메뉴",0,IF($D15="프렙",IFERROR(VLOOKUP($E15,'② 프렙 원가'!$B$6:$F$16,5,FALSE),0),IFERROR(VLOOKUP($E15,'① 식재료 단가'!$B$6:$G$123,6,FALSE),0)))) | K15: =IF($D15="메뉴",ROUND($G15*$J15,1),IF($I15>0,ROUND($G15/$I15*$J15,1),0))
A16: 🍗 치킨 커리 | B16: 베이비 커리 | C16: 4 | D16: 식재료 | E16: 멸균우유 | G16: 15 | H16: g | I16: 1 | J16: =IF($D16="무료",0,IF($D16="메뉴",0,IF($D16="프렙",IFERROR(VLOOKUP($E16,'② 프렙 원가'!$B$6:$F$16,5,FALSE),0),IFERROR(VLOOKUP($E16,'① 식재료 단가'!$B$6:$G$123,6,FALSE),0)))) | K16: =IF($D16="메뉴",ROUND($G16*$J16,1),IF($I16>0,ROUND($G16/$I16*$J16,1),0)) | L16: 농도 조절
A17: 🍗 치킨 커리 | B17: 베이비 커리 | C17: 5 | D17: 식재료 | E17: 꽃소금 | G17: 3 | H17: g | I17: 1 | J17: =IF($D17="무료",0,IF($D17="메뉴",0,IF($D17="프렙",IFERROR(VLOOKUP($E17,'② 프렙 원가'!$B$6:$F$16,5,FALSE),0),IFERROR(VLOOKUP($E17,'① 식재료 단가'!$B$6:$G$123,6,FALSE),0)))) | K17: =IF($D17="메뉴",ROUND($G17*$J17,1),IF($I17>0,ROUND($G17/$I17*$J17,1),0))
A18: 🍗 치킨 커리 | B18: 스페셜 커리치킨 | C18: 1 | D18: 식재료 | E18: 가슴 대한 | F18: 닭가슴살 (정육) | G18: 60 | H18: g | I18: 1 | J18: =IF($D18="무료",0,IF($D18="메뉴",0,IF($D18="프렙",IFERROR(VLOOKUP($E18,'② 프렙 원가'!$B$6:$F$16,5,FALSE),0),IFERROR(VLOOKUP($E18,'① 식재료 단가'!$B$6:$G$123,6,FALSE),0)))) | K18: =IF($D18="메뉴",ROUND($G18*$J18,1),IF($I18>0,ROUND($G18/$I18*$J18,1),0)) | L18: 깍뚝썰기
A19: 🍗 치킨 커리 | B19: 스페셜 커리치킨 | C19: 2 | D19: 프렙 | E19: 커리 그레이비 소스 | G19: 120 | H19: g | I19: 1 | J19: =IF($D19="무료",0,IF($D19="메뉴",0,IF($D19="프렙",IFERROR(VLOOKUP($E19,'② 프렙 원가'!$B$6:$F$16,5,FALSE),0),IFERROR(VLOOKUP($E19,'① 식재료 단가'!$B$6:$G$123,6,FALSE),0)))) | K19: =IF($D19="메뉴",ROUND($G19*$J19,1),IF($I19>0,ROUND($G19/$I19*$J19,1),0))
A20: 🍗 치킨 커리 | B20: 스페셜 커리치킨 | C20: 3 | D20: 식재료 | E20: 캐슈넛 | G20: 5 | H20: g | I20: 1 | J20: =IF($D20="무료",0,IF($D20="메뉴",0,IF($D20="프렙",IFERROR(VLOOKUP($E20,'② 프렙 원가'!$B$6:$F$16,5,FALSE),0),IFERROR(VLOOKUP($E20,'① 식재료 단가'!$B$6:$G$123,6,FALSE),0)))) | K20: =IF($D20="메뉴",ROUND($G20*$J20,1),IF($I20>0,ROUND($G20/$I20*$J20,1),0))
A21: 🍗 치킨 커리 | B21: 스페셜 커리치킨 | C21: 4 | D21: 식재료 | E21: 계란 | G21: 5 | H21: g | I21: 1 | J21: =IF($D21="무료",0,IF($D21="메뉴",0,IF($D21="프렙",IFERROR(VLOOKUP($E21,'② 프렙 원가'!$B$6:$F$16,5,FALSE),0),IFERROR(VLOOKUP($E21,'① 식재료 단가'!$B$6:$G$123,6,FALSE),0)))) | K21: =IF($D21="메뉴",ROUND($G21*$J21,1),IF($I21>0,ROUND($G21/$I21*$J21,1),0)) | L21: 삶아서 반으로 자르기
A22: 🍗 치킨 커리 | B22: 스페셜 커리치킨 | C22: 5 | D22: 식재료 | E22: 설탕 | G22: 20 | H22: g | I22: 1 | J22: =IF($D22="무료",0,IF($D22="메뉴",0,IF($D22="프렙",IFERROR(VLOOKUP($E22,'② 프렙 원가'!$B$6:$F$16,5,FALSE),0),IFERROR(VLOOKUP($E22,'① 식재료 단가'!$B$6:$G$123,6,FALSE),0)))) | K22: =IF($D22="메뉴",ROUND($G22*$J22,1),IF($I22>0,ROUND($G22/$I22*$J22,1),0))
A23: 🍗 치킨 커리 | B23: 스페셜 커리치킨 | C23: 6 | D23: 식재료 | E23: 꽃소금 | G23: 15 | H23: g | I23: 1 | J23: =IF($D23="무료",0,IF($D23="메뉴",0,IF($D23="프렙",IFERROR(VLOOKUP($E23,'② 프렙 원가'!$B$6:$F$16,5,FALSE),0),IFERROR(VLOOKUP($E23,'① 식재료 단가'!$B$6:$G$123,6,FALSE),0)))) | K23: =IF($D23="메뉴",ROUND($G23*$J23,1),IF($I23>0,ROUND($G23/$I23*$J23,1),0))
A24: 🍗 치킨 커리 | B24: 스페셜 커리치킨 | C24: 7 | D24: 식재료 | E24: 데어리쿠킹크림 | G24: 20 | H24: g | I24: 1 | J24: =IF($D24="무료",0,IF($D24="메뉴",0,IF($D24="프렙",IFERROR(VLOOKUP($E24,'② 프렙 원가'!$B$6:$F$16,5,FALSE),0),IFERROR(VLOOKUP($E24,'① 식재료 단가'!$B$6:$G$123,6,FALSE),0)))) | K24: =IF($D24="메뉴",ROUND($G24*$J24,1),IF($I24>0,ROUND($G24/$I24*$J24,1),0))
A25: 🍗 치킨 커리 | B25: 스페셜 커리치킨 | C25: 8 | D25: 식재료 | E25: ASEEL PURE GHEE | G25: 5 | H25: g | I25: 1 | J25: =IF($D25="무료",0,IF($D25="메뉴",0,IF($D25="프렙",IFERROR(VLOOKUP($E25,'② 프렙 원가'!$B$6:$F$16,5,FALSE),0),IFERROR(VLOOKUP($E25,'① 식재료 단가'!$B$6:$G$123,6,FALSE),0)))) | K25: =IF($D25="메뉴",ROUND($G25*$J25,1),IF($I25>0,ROUND($G25/$I25*$J25,1),0))
A26: 🍗 치킨 커리 | B26: 진저 치킨 | C26: 1 | D26: 식재료 | E26: 가슴 대한 | F26: 닭가슴살 (정육) | G26: 70 | H26: g | I26: 1 | J26: =IF($D26="무료",0,IF($D26="메뉴",0,IF($D26="프렙",IFERROR(VLOOKUP($E26,'② 프렙 원가'!$B$6:$F$16,5,FALSE),0),IFERROR(VLOOKUP($E26,'① 식재료 단가'!$B$6:$G$123,6,FALSE),0)))) | K26: =IF($D26="메뉴",ROUND($G26*$J26,1),IF($I26>0,ROUND($G26/$I26*$J26,1),0)) | L26: 깍뚝썰기
A27: 🍗 치킨 커리 | B27: 진저 치킨 | C27: 2 | D27: 식재료 | E27: 통생강 | G27: 10 | H27: g | I27: 1 | J27: =IF($D27="무료",0,IF($D27="메뉴",0,IF($D27="프렙",IFERROR(VLOOKUP($E27,'② 프렙 원가'!$B$6:$F$16,5,FALSE),0),IFERROR(VLOOKUP($E27,'① 식재료 단가'!$B$6:$G$123,6,FALSE),0)))) | K27: =IF($D27="메뉴",ROUND($G27*$J27,1),IF($I27>0,ROUND($G27/$I27*$J27,1),0)) | L27: 곱게 채 썰기
A28: 🍗 치킨 커리 | B28: 진저 치킨 | C28: 3 | D28: 프렙 | E28: 커리 그레이비 소스 | G28: 120 | H28: g | I28: 1 | J28: =IF($D28="무료",0,IF($D28="메뉴",0,IF($D28="프렙",IFERROR(VLOOKUP($E28,'② 프렙 원가'!$B$6:$F$16,5,FALSE),0),IFERROR(VLOOKUP($E28,'① 식재료 단가'!$B$6:$G$123,6,FALSE),0)))) | K28: =IF($D28="메뉴",ROUND($G28*$J28,1),IF($I28>0,ROUND($G28/$I28*$J28,1),0))
A29: 🍗 치킨 커리 | B29: 진저 치킨 | C29: 4 | D29: 식재료 | E29: 옥수수전분 | G29: 50 | H29: g | I29: 1 | J29: =IF($D29="무료",0,IF($D29="메뉴",0,IF($D29="프렙",IFERROR(VLOOKUP($E29,'② 프렙 원가'!$B$6:$F$16,5,FALSE),0),IFERROR(VLOOKUP($E29,'① 식재료 단가'!$B$6:$G$123,6,FALSE),0)))) | K29: =IF($D29="메뉴",ROUND($G29*$J29,1),IF($I29>0,ROUND($G29/$I29*$J29,1),0)) | L29: 튀김 코팅
A30: 🍗 치킨 커리 | B30: 진저 치킨 | C30: 5 | D30: 식재료 | E30: 설탕 | G30: 15 | H30: g | I30: 1 | J30: =IF($D30="무료",0,IF($D30="메뉴",0,IF($D30="프렙",IFERROR(VLOOKUP($E30,'② 프렙 원가'!$B$6:$F$16,5,FALSE),0),IFERROR(VLOOKUP($E30,'① 식재료 단가'!$B$6:$G$123,6,FALSE),0)))) | K30: =IF($D30="메뉴",ROUND($G30*$J30,1),IF($I30>0,ROUND($G30/$I30*$J30,1),0))
A31: 🍗 치킨 커리 | B31: 진저 치킨 | C31: 6 | D31: 식재료 | E31: 꽃소금 | G31: 15 | H31: g | I31: 1 | J31: =IF($D31="무료",0,IF($D31="메뉴",0,IF($D31="프렙",IFERROR(VLOOKUP($E31,'② 프렙 원가'!$B$6:$F$16,5,FALSE),0),IFERROR(VLOOKUP($E31,'① 식재료 단가'!$B$6:$G$123,6,FALSE),0)))) | K31: =IF($D31="메뉴",ROUND($G31*$J31,1),IF($I31>0,ROUND($G31/$I31*$J31,1),0))
A32: 🍗 치킨 커리 | B32: 진저 치킨 | C32: 7 | D32: 식재료 | E32: 식용유 | G32: 20 | H32: 적당량(20g 추정) | I32: 1 | J32: =IF($D32="무료",0,IF($D32="메뉴",0,IF($D32="프렙",IFERROR(VLOOKUP($E32,'② 프렙 원가'!$B$6:$F$16,5,FALSE),0),IFERROR(VLOOKUP($E32,'① 식재료 단가'!$B$6:$G$123,6,FALSE),0)))) | K32: =IF($D32="메뉴",ROUND($G32*$J32,1),IF($I32>0,ROUND($G32/$I32*$J32,1),0)) | L32: 튀김용
A33: 🍗 치킨 커리 | B33: 치킨 마살라 | C33: 1 | D33: 식재료 | E33: 가슴 대한 | F33: 닭가슴살 (정육) | G33: 55 | H33: g | I33: 1 | J33: =IF($D33="무료",0,IF($D33="메뉴",0,IF($D33="프렙",IFERROR(VLOOKUP($E33,'② 프렙 원가'!$B$6:$F$16,5,FALSE),0),IFERROR(VLOOKUP($E33,'① 식재료 단가'!$B$6:$G$123,6,FALSE),0)))) | K33: =IF($D33="메뉴",ROUND($G33*$J33,1),IF($I33>0,ROUND($G33/$I33*$J33,1),0)) | L33: 깍뚝썰기
A34: 🍗 치킨 커리 | B34: 치킨 마살라 | C34: 2 | D34: 프렙 | E34: 커리 그레이비 소스 | G34: 110 | H34: g | I34: 1 | J34: =IF($D34="무료",0,IF($D34="메뉴",0,IF($D34="프렙",IFERROR(VLOOKUP($E34,'② 프렙 원가'!$B$6:$F$16,5,FALSE),0),IFERROR(VLOOKUP($E34,'① 식재료 단가'!$B$6:$G$123,6,FALSE),0)))) | K34: =IF($D34="메뉴",ROUND($G34*$J34,1),IF($I34>0,ROUND($G34/$I34*$J34,1),0)) | L34: 사전 조리된 베이스
A35: 🍗 치킨 커리 | B35: 치킨 마살라 | C35: 3 | D35: 식재료 | E35: 계란 | G35: 30 | H35: g | I35: 1 | J35: =IF($D35="무료",0,IF($D35="메뉴",0,IF($D35="프렙",IFERROR(VLOOKUP($E35,'② 프렙 원가'!$B$6:$F$16,5,FALSE),0),IFERROR(VLOOKUP($E35,'① 식재료 단가'!$B$6:$G$123,6,FALSE),0)))) | K35: =IF($D35="메뉴",ROUND($G35*$J35,1),IF($I35>0,ROUND($G35/$I35*$J35,1),0)) | L35: 삶아서 반으로 자르기
A36: 🍗 치킨 커리 | B36: 치킨 마살라 | C36: 4 | D36: 식재료 | E36: 토마토 | G36: 10 | H36: g | I36: 1 | J36: =IF($D36="무료",0,IF($D36="메뉴",0,IF($D36="프렙",IFERROR(VLOOKUP($E36,'② 프렙 원가'!$B$6:$F$16,5,FALSE),0),IFERROR(VLOOKUP($E36,'① 식재료 단가'!$B$6:$G$123,6,FALSE),0)))) | K36: =IF($D36="메뉴",ROUND($G36*$J36,1),IF($I36>0,ROUND($G36/$I36*$J36,1),0)) | L36: 다지기
A37: 🍗 치킨 커리 | B37: 치킨 마살라 | C37: 5 | D37: 식재료 | E37: 청양고추 | G37: 15 | H37: g | I37: 1 | J37: =IF($D37="무료",0,IF($D37="메뉴",0,IF($D37="프렙",IFERROR(VLOOKUP($E37,'② 프렙 원가'!$B$6:$F$16,5,FALSE),0),IFERROR(VLOOKUP($E37,'① 식재료 단가'!$B$6:$G$123,6,FALSE),0)))) | K37: =IF($D37="메뉴",ROUND($G37*$J37,1),IF($I37>0,ROUND($G37/$I37*$J37,1),0)) | L37: 어슷썰기
A38: 🍗 치킨 커리 | B38: 치킨 마살라 | C38: 6 | D38: 식재료 | E38: 완두콩 | G38: 10 | H38: g | I38: 1 | J38: =IF($D38="무료",0,IF($D38="메뉴",0,IF($D38="프렙",IFERROR(VLOOKUP($E38,'② 프렙 원가'!$B$6:$F$16,5,FALSE),0),IFERROR(VLOOKUP($E38,'① 식재료 단가'!$B$6:$G$123,6,FALSE),0)))) | K38: =IF($D38="메뉴",ROUND($G38*$J38,1),IF($I38>0,ROUND($G38/$I38*$J38,1),0))
A39: 🍗 치킨 커리 | B39: 치킨 마살라 | C39: 7 | D39: 식재료 | E39: 꽃소금 | G39: 5 | H39: g | I39: 1 | J39: =IF($D39="무료",0,IF($D39="메뉴",0,IF($D39="프렙",IFERROR(VLOOKUP($E39,'② 프렙 원가'!$B$6:$F$16,5,FALSE),0),IFERROR(VLOOKUP($E39,'① 식재료 단가'!$B$6:$G$123,6,FALSE),0)))) | K39: =IF($D39="메뉴",ROUND($G39*$J39,1),IF($I39>0,ROUND($G39/$I39*$J39,1),0))
A40: 🍗 치킨 커리 | B40: 치킨 마살라 | C40: 8 | D40: 식재료 | E40: 데어리쿠킹크림 | G40: 15 | H40: g | I40: 1 | J40: =IF($D40="무료",0,IF($D40="메뉴",0,IF($D40="프렙",IFERROR(VLOOKUP($E40,'② 프렙 원가'!$B$6:$F$16,5,FALSE),0),IFERROR(VLOOKUP($E40,'① 식재료 단가'!$B$6:$G$123,6,FALSE),0)))) | K40: =IF($D40="메뉴",ROUND($G40*$J40,1),IF($I40>0,ROUND($G40/$I40*$J40,1),0))
A41: 🍗 치킨 커리 | B41: 치킨 빈달루 | C41: 1 | D41: 식재료 | E41: 가슴 대한 | F41: 닭가슴살 (정육) | G41: 70 | H41: g | I41: 1 | J41: =IF($D41="무료",0,IF($D41="메뉴",0,IF($D41="프렙",IFERROR(VLOOKUP($E41,'② 프렙 원가'!$B$6:$F$16,5,FALSE),0),IFERROR(VLOOKUP($E41,'① 식재료 단가'!$B$6:$G$123,6,FALSE),0)))) | K41: =IF($D41="메뉴",ROUND($G41*$J41,1),IF($I41>0,ROUND($G41/$I41*$J41,1),0)) | L41: 깍뚝썰기
...

Sheet ① 식재료 단가
A1: ① 식재료 단가
A2: 노란 셀(구매가격·규격)만 수정하세요. 단가와 전체 메뉴 원가가 자동으로 다시 계산됩니다.
A3: 💡 무게로 사는 것은 단가 = 구매가격 ÷ 총중량(g). 캔·포장용기처럼 개수로 사는 것은 단가 = 구매가격 ÷ 규격수량(원/개).
A5: No. | B5: 식재료명 | C5: 구매가격(원) | D5: 규격수량 | E5: 단위 | F5: 총중량(g) | G5: 단가 (원/g·원/개) | H5: 비고
A6: 1 | B6: 중2등급 밀가루 | C6: 15000 | D6: 20 | E6: kg | F6: 20000 | G6: =IF(F6>0,C6/F6,0)
A7: 2 | B7: 고급 밀가루 | C7: 25000 | D7: 20 | E7: kg | F7: 20000 | G7: =IF(F7>0,C7/F7,0)
A8: 3 | B8: 국내산쌀 | C8: 62000 | D8: 20 | E8: kg | F8: 20000 | G8: =IF(F8>0,C8/F8,0)
A9: 4 | B9: 양파 | C9: 14000 | D9: 15 | E9: kg | F9: 15000 | G9: =IF(F9>0,C9/F9,0)
A10: 5 | B10: 감자 | C10: 35000 | D10: 20 | E10: kg | F10: 20000 | G10: =IF(F10>0,C10/F10,0)
A11: 6 | B11: 주름감자(프렌치프라이) | C11: 8300 | D11: 2 | E11: kg | F11: 2000 | G11: =IF(F11>0,C11/F11,0)
A12: 7 | B12: 통생강 | C12: 10000 | D12: 1 | E12: kg | F12: 1000 | G12: =IF(F12>0,C12/F12,0)
A13: 8 | B13: 통마늘 | C13: 7850 | D13: 1 | E13: kg | F13: 1000 | G13: =IF(F13>0,C13/F13,0)
A14: 9 | B14: 고운 고추가루 | C14: 14000 | D14: 1 | E14: kg | F14: 1000 | G14: =IF(F14>0,C14/F14,0)
A15: 10 | B15: 베트남(고추가루) | C15: 18000 | D15: 1 | E15: kg | F15: 1000 | G15: =IF(F15>0,C15/F15,0)
A16: 11 | B16: 베트남(건고추) | C16: 17000 | D16: 1 | E16: kg | F16: 1000 | G16: =IF(F16>0,C16/F16,0)
A17: 12 | B17: 통계피 | C17: 5000 | D17: 0.5 | E17: kg | F17: 500 | G17: =IF(F17>0,C17/F17,0)
... A25: 20 | B25: 스파게티면 | C25: 1250 | D25: 0.5 | E25: kg | F25: 500 | G25: =IF(F25>0,C25/F25,0)
A26: 21 | B26: 딸기잼 | C26: 0 | D26: 3 | E26: kg | F26: 3000 | G26: =IF(F26>0,C26/F26,0) | H26: ⚠ 구매가격 입력 필요
A27: 22 | B27: 토마토홀 | C27: 6000 | D27: 2.5 | E27: kg | F27: 2500 | G27: =IF(F27>0,C27/F27,0)
A28: 23 | B28: 케찹스파우트 | C28: 6650 | D28: 3.2 | E28: kg | F28: 3200 | G28: =IF(F28>0,C28/F28,0)
A29: 24 | B29: 키위드레싱소스 | C29: 12000 | D29: 2 | E29: kg | F29: 2000 | G29: =IF(F29>0,C29/F29,0)
A30: 25 | B30: 딥/칠리/스위트 소스 | C30: 18000 | D30: 5.9 | E30: kg | F30: 5900 | G30: =IF(F30>0,C30/F30,0)
A31: 26 | B31: 백후추가루 | C31: 9000 | D31: 0.4 | E31: kg | F31: 400 | G31: =IF(F31>0,C31/F31,0)
A32: 27 | B32: 흑후추가루 | C32: 9000 | D32: 0.4 | E32: kg | F32: 400 | G32: =IF(F32>0,C32/F32,0)
A33: 28 | B33: 탈각새우31/40 | C33: 15200 | D33: 0.9 | E33: kg | F33: 900 | G33: =IF(F33>0,C33/F33,0)
A34: 29 | B34: 찐새우살 | C34: 15000 | D34: 0.9 | E34: kg | F34: 900 | G34: =IF(F34>0,C34/F34,0)
A35: 30 | B35: 해물모듬 | C35: 4750 | D35: 0.6 | E35: kg | F35: 600 | G35: =IF(F35>0,C35/F35,0)
A36: 31 | B36: 간장 | C36: 5500 | D36: 1.5 | E36: kg | F36: 1800 | G36: =IF(F36>0,C36/F36,0)
A37: 32 | B37: 꽃소금 | C37: 15000 | D37: 15 | E37: kg | F37: 15000 | G37: =IF(F37>0,C37/F37,0)
A38: 33 | B38: 설탕 | C38: 20000 | D38: 15 | E38: kg | F38: 15000 | G38: =IF(F38>0,C38/F38,0)
... A62: 57 | B62: 참기름 | C62: 24000 | D62: 1 | E62: kg | F62: 1000 | G62: =IF(F62>0,C62/F62,0)
A63: 58 | B63: 콜라_24개 | C63: 21000 | D63: 0 | E63: kg | F63: 0 | G63: =IF(F63>0,C63/F63,0) | H63: ⚠ 총중량(g) 입력 필요 — 개수 품목이면 「개수 단위」로 바꾸세요
A64: 59 | B64: 사이다_24개 | C64: 19500 | D64: 0 | E64: kg | F64: 0 | G64: =IF(F64>0,C64/F64,0) | H64: ⚠ 총중량(g) 입력 필요 — 개수 품목이면 「개수 단위」로 바꾸세요
A65: 60 | B65: 레몬 | C65: 900 | D65: 0.1 | E65: kg | F65: 100 | G65: =IF(F65>0,C65/F65,0)
A66: 61 | B66: 닭 09호 | C66: 4400 | D66: 0.9 | E66: kg | F66: 900 | G66: =IF(F66>0,C66/F66,0)
A67: 62 | B67: 닭 13호 | C67: 6000 | D67: 1.3 | E67: kg | F67: 1300 | G67: =IF(F67>0,C67/F67,0)
A68: 63 | B68: 가슴 대한 | C68: 4400 | D68: 1 | E68: kg | F68: 1000 | G68: =IF(F68>0,C68/F68,0)
A69: 64 | B69: 북채 | C69: 7200 | D69: 1 | E69: kg | F69: 1000 | G69: =IF(F69>0,C69/F69,0)
A70: 65 | B70: 정육(부위 닭) | C70: 5000 | D70: 1 | E70: kg | F70: 1000 | G70: =IF(F70>0,C70/F70,0)
A71: 66 | B71: 근위(똥집) | C71: 4400 | D71: 1 | E71: kg | F71: 1000 | G71: =IF(F71>0,C71/F71,0)
...

Sheet ② 프렙 원가
A1: ② 프렙(반제품) 원가
A2: 커리 그레이비·탄두리 소스처럼 미리 만들어 두는 반제품의 g당 원가입니다. 투입량과 완성중량만 고치면 됩니다.
A3: 💡 g당 원가 = 총 재료비 ÷ 완성중량(g). 아래 [투입 재료 상세]의 투입량을 바꾸면 총 재료비가 자동 반영됩니다.
A5: No. | B5: 프렙 제품명 | C5: 완성중량(g) | D5: 수율 | E5: 총 재료비(원) | F5: g당 원가(원) | G5: 투입중량(g) | H5: 비고
A6: 1 | B6: 커리 그레이비 소스 | C6: 59904 | D6: 0.78 | E6: =SUMIF($A$21:$A$66,$B6,$F$21:$F$66) | F6: =IF(C6>0,E6/C6,0) | G6: =SUMIF($A$21:$A$66,$B6,$D$21:$D$66)
A7: 2 | B7: 펄럭(시금치) 소스 | C7: 1048 | D7: 0.8 | E7: =SUMIF($A$21:$A$66,$B7,$F$21:$F$66) | F7: =IF(C7>0,E7/C7,0) | G7: =SUMIF($A$21:$A$66,$B7,$D$21:$D$66)
A8: 3 | B8: 치즈 | C8: 4950 | D8: 0.15 | E8: =SUMIF($A$21:$A$66,$B8,$F$21:$F$66) | F8: =IF(C8>0,E8/C8,0) | G8: =SUMIF($A$21:$A$66,$B8,$D$21:$D$66)
A9: 4 | B9: 베이비커리 | C9: 1402.5 | D9: 0.85 | E9: =SUMIF($A$21:$A$66,$B9,$F$21:$F$66) | F9: =IF(C9>0,E9/C9,0) | G9: =SUMIF($A$21:$A$66,$B9,$D$21:$D$66)
A10: 5 | B10: 요거트 | C10: 1200 | D10: 1 | E10: =SUMIF($A$21:$A$66,$B10,$F$21:$F$66) | F10: =IF(C10>0,E10/C10,0) | G10: =SUMIF($A$21:$A$66,$B10,$D$21:$D$66)
A11: 6 | B11: 달머커니 소스 | C11: 1520 | D11: 0.95 | E11: =SUMIF($A$21:$A$66,$B11,$F$21:$F$66) | F11: =IF(C11>0,E11/C11,0) | G11: =SUMIF($A$21:$A$66,$B11,$D$21:$D$66)
A12: 7 | B12: 마늘생강 페이스트 | C12: 900 | D12: 0.9 | E12: =SUMIF($A$21:$A$66,$B12,$F$21:$F$66) | F12: =IF(C12>0,E12/C12,0) | G12: =SUMIF($A$21:$A$66,$B12,$D$21:$D$66)
A13: 8 | B13: 탄두리 샐러드 | C13: 22.8 | D13: 0.6 | E13: =SUMIF($A$21:$A$66,$B13,$F$21:$F$66) | F13: =IF(C13>0,E13/C13,0) | G13: =SUMIF($A$21:$A$66,$B13,$D$21:$D$66)
A14: 9 | B14: 탄두리 소스 | C14: 2000 | D14: 1 | E14: =SUMIF($A$67:$A$89,$B14,$F$67:$F$89) | F14: =IF(C14>0,E14/C14,0) | G14: =SUMIF($A$67:$A$89,$B14,$D$67:$D$89)
A15: 10 | B15: 고수 소스 | C15: 549 | D15: 0.6 | E15: =SUMIF($A$67:$A$89,$B15,$F$67:$F$89) | F15: =IF(C15>0,E15/C15,0) | G15: =SUMIF($A$67:$A$89,$B15,$D$67:$D$89)
A16: 11 | B16: 라씨 | C16: 2000 | D16: 1 | E16: =SUMIF($A$67:$A$89,$B16,$F$67:$F$89) | F16: =IF(C16>0,E16/C16,0) | G16: =SUMIF($A$67:$A$89,$B16,$D$67:$D$89)
A18: ▸ 투입 재료 상세 ─ 투입량(노란 셀)만 수정하세요
A20: 프렙 제품명 | B20: 구분 | C20: 재료명 | D20: 투입량(g) | E20: g당 단가(원) | F20: 재료비(원)
A21: 커리 그레이비 소스 | B21: 식재료 | C21: 양파 | D21: 60000 | E21: =IFERROR(VLOOKUP($C21,'① 식재료 단가'!$B$6:$G$123,6,FALSE),0) | F21: =ROUND($D21*$E21,2)
A22: 커리 그레이비 소스 | B22: 식재료 | C22: 통마늘 | D22: 1000 | E22: =IFERROR(VLOOKUP($C22,'① 식재료 단가'!$B$6:$G$123,6,FALSE),0) | F22: =ROUND($D22*$E22,2)
A23: 커리 그레이비 소스 | B23: 식재료 | C23: 땅콩 | D23: 4000 | E23: =IFERROR(VLOOKUP($C23,'① 식재료 단가'!$B$6:$G$123,6,FALSE),0) | F23: =ROUND($D23*$E23,2)
A24: 커리 그레이비 소스 | B24: 식재료 | C24: 호박씨 | D24: 3000 | E24: =IFERROR(VLOOKUP($C24,'① 식재료 단가'!$B$6:$G$123,6,FALSE),0) | F24: =ROUND($D24*$E24,2)
A25: 커리 그레이비 소스 | B25: 식재료 | C25: 통생강 | D25: 1000 | E25: =IFERROR(VLOOKUP($C25,'① 식재료 단가'!$B$6:$G$123,6,FALSE),0) | F25: =ROUND($D25*$E25,2)
A26: 커리 그레이비 소스 | B26: 식재료 | C26: CUMIN powder | D26: 400 | E26: =IFERROR(VLOOKUP($C26,'① 식재료 단가'!$B$6:$G$123,6,FALSE),0) | F26: =ROUND($D26*$E26,2)
A27: 커리 그레이비 소스 | B27: 식재료 | C27: 카다멈 | D27: 200 | E27: =IFERROR(VLOOKUP($C27,'① 식재료 단가'!$B$6:$G$123,6,FALSE),0) | F27: =ROUND($D27*$E27,2)
A28: 커리 그레이비 소스 | B28: 식재료 | C28: 치킨마살라 파우더 | D28: 200 | E28: =IFERROR(VLOOKUP($C28,'① 식재료 단가'!$B$6:$G$123,6,FALSE),0) | F28: =ROUND($D28*$E28,2)
A29: 커리 그레이비 소스 | B29: 식재료 | C29: 머튼마살라 파우더 | D29: 200 | E29: =IFERROR(VLOOKUP($C29,'① 식재료 단가'!$B$6:$G$123,6,FALSE),0) | F29: =ROUND($D29*$E29,2)
A30: 커리 그레이비 소스 | B30: 식재료 | C30: 식용유 | D30: 3000 | E30: =IFERROR(VLOOKUP($C30,'① 식재료 단가'!$B$6:$G$123,6,FALSE),0) | F30: =ROUND($D30*$E30,2)
A31: 커리 그레이비 소스 | B31: 식재료 | C31: TURMERIC POWDER | D31: 400 | E31: =IFERROR(VLOOKUP($C31,'① 식재료 단가'!$B$6:$G$123,6,FALSE),0) | F31: =ROUND($D31*$E31,2)
A32: 커리 그레이비 소스 | B32: 식재료 | C32: 고운 고추가루 | D32: 400 | E32: =IFERROR(VLOOKUP($C32,'① 식재료 단가'!$B$6:$G$123,6,FALSE),0) | F32: =ROUND($D32*$E32,2)
... A66: 탄두리 샐러드 | B66: 식재료 | C66: 꽃소금 | D66: 5 | E66: =IFERROR(VLOOKUP($C66,'① 식재료 단가'!$B$6:$G$123,6,FALSE),0) | F66: =ROUND($D66*$E66,2)
A67: 탄두리 소스 | B67: 식재료 | C67: 고운 고추가루 | D67: 200 | E67: =IF($B67="프렙",IFERROR(VLOOKUP($C67,'② 프렙 원가'!$B$6:$F$13,5,FALSE),0),IFERROR(VLOOKUP($C67,'① 식재료 단가'!$B$6:$G$123,6,FALSE),0)) | F67: =ROUND($D67*$E67,2)
A68: 탄두리 소스 | B68: 프렙 | C68: 요거트 | D68: 1000 | E68: =IF($B68="프렙",IFERROR(VLOOKUP($C68,'② 프렙 원가'!$B$6:$F$13,5,FALSE),0),IFERROR(VLOOKUP($C68,'① 식재료 단가'!$B$6:$G$123,6,FALSE),0)) | F68: =ROUND($D68*$E68,2)
A69: 탄두리 소스 | B69: 식재료 | C69: 치킨마살라 파우더 | D69: 100 | E69: =IF($B69="프렙",IFERROR(VLOOKUP($C69,'② 프렙 원가'!$B$6:$F$13,5,FALSE),0),IFERROR(VLOOKUP($C69,'① 식재료 단가'!$B$6:$G$123,6,FALSE),0)) | F69: =ROUND($D69*$E69,2)
A70: 탄두리 소스 | B70: 식재료 | C70: 머튼마살라 파우더 | D70: 100 | E70: =IF($B70="프렙",IFERROR(VLOOKUP($C70,'② 프렙 원가'!$B$6:$F$13,5,FALSE),0),IFERROR(VLOOKUP($C70,'① 식재료 단가'!$B$6:$G$123,6,FALSE),0)) | F70: =ROUND($D70*$E70,2)
A71: 탄두리 소스 | B71: 식재료 | C71: CUMIN powder | D71: 100 | E71: =IF($B71="프렙",IFERROR(VLOOKUP($C71,'② 프렙 원가'!$B$6:$F$13,5,FALSE),0),IFERROR(VLOOKUP($C71,'① 식재료 단가'!$B$6:$G$123,6,FALSE),0)) | F71: =ROUND($D71*$E71,2)
A72: 탄두리 소스 | B72: 식재료 | C72: CHAAT MASALA (MEHRAN) | D72: 50 | E72: =IF($B72="프렙",IFERROR(VLOOKUP($C72,'② 프렙 원가'!$B$6:$F$13,5,FALSE),0),IFERROR(VLOOKUP($C72,'① 식재료 단가'!$B$6:$G$123,6,FALSE),0)) | F72: =ROUND($D72*$E72,2)
A73: 탄두리 소스 | B73: 식재료 | C73: 통마늘 | D73: 200 | E73: =IF($B73="프렙",IFERROR(VLOOKUP($C73,'② 프렙 원가'!$B$6:$F$13,5,FALSE),0),IFERROR(VLOOKUP($C73,'① 식재료 단가'!$B$6:$G$123,6,FALSE),0)) | F73: =ROUND($D73*$E73,2)
A74: 탄두리 소스 | B74: 식재료 | C74: 통생강 | D74: 200 | E74: =IF($B74="프렙",IFERROR(VLOOKUP($C74,'② 프렙 원가'!$B$6:$F$13,5,FALSE),0),IFERROR(VLOOKUP($C74,'① 식재료 단가'!$B$6:$G$123,6,FALSE),0)) | F74: =ROUND($D74*$E74,2)
A75: 탄두리 소스 | B75: 식재료 | C75: 환만식초 | D75: 25 | E75: =IF($B75="프렙",IFERROR(VLOOKUP($C75,'② 프렙 원가'!$B$6:$F$13,5,FALSE),0),IFERROR(VLOOKUP($C75,'① 식재료 단가'!$B$6:$G$123,6,FALSE),0)) | F75: =ROUND($D75*$E75,2)
A76: 탄두리 소스 | B76: 식재료 | C76: 식용유 | D76: 20 | E76: =IF($B76="프렙",IFERROR(VLOOKUP($C76,'② 프렙 원가'!$B$6:$F$13,5,FALSE),0),IFERROR(VLOOKUP($C76,'① 식재료 단가'!$B$6:$G$123,6,FALSE),0)) | F76: =ROUND($D76*$E76,2)
...

Sheet ③ 고정비 설정
A1: ③ 고정비 설정
A2: 월 고정비와 월 추정매출을 입력하면, 메뉴별 고정비 배분액이 판매가에 비례해 자동 계산됩니다.
A3: 💡 메뉴 1개당 고정비 배분 = 판매가 × (배분대상 고정비 합계 ÷ 월 추정매출)
A5: No. | B5: 비용 항목 | C5: 월간 금액(원) | D5: 배분 포함 | E5: 내용 / 비고
A6: 1 | B6: 급여 | C6: 12000000 | D6: 포함 | E6: 임금
A7: 2 | B7: 세금·지방세 | C7: 205800 | D7: 포함 | E7: 세금신고 + 지방세
A8: 3 | B8: 4대 보험료 | C8: 2336970 | D8: 포함 | E8: 사업장 4대 보험 (사용자 부담분)
A9: 4 | B9: 유틸리티 | C9: 783420 | D9: 포함 | E9: 수도·전기·가스
A10: 5 | B10: 부가가치세 | C10: 8800000 | D10: 포함 | E10: 배달의민족·쿠팡이츠 등
A11: 6 | B11: 포장 용품비 | C11: 50000 | D11: 포함 | E11: 포장재료비
A12: 7 | B12: 임대 및 광고비 | C12: 3894139 | D12: 포함 | E12: 임대료, 인터넷 마케팅, 대리운전 광고 등
A13: 8 | B13: 외상 매입금-식재료비 | C13: 17000000 | D13: 제외 | E13: 식재료 원가로 이미 반영 → 고정비 배분에서 제외 (필요 시 포함으로 변경)
A14: 9 | B14: 주류대금 | C14: 204000 | D14: 포함 | E14: 주류구입
A15: 10 | B15: 세무·장부 수수료 | C15: 391270 | D15: 포함 | E15: 세무신고 + 증빙 수수료
A16: 11 | B16: 기타 관리비 | C16: 703730 | D16: 포함 | E16: 잡비 기타
A17: 12 | B17: 통신비 | C17: 48950 | D17: 포함 | E17: KT 등 통신
A18: 13 | B18: 식재료 공급 계약비 | C18: 256800 | D18: 제외 | E18: 식재료 원가로 이미 반영 → 고정비 배분에서 제외 (필요 시 포함으로 변경)
A19: 고정비 총계 | C19: =SUM(C6:C18) | E19: 입력한 모든 항목의 합계
A20: 배분 대상 합계 | C20: =SUMIF(D6:D18,"포함",C6:C18) | E20: 「배분 포함」인 항목만 합산 → 메뉴 원가에 반영
A22: ▸ 부가세 · 배분 · 판정 기준 설정
A23: 부가세 처리 | C23: 포함 | E23: 판매가가 손님이 내는 금액이면 「포함」, 공급가액이면 「별도」
A24: 부가세율 | C24: 0.1 | E24: 「포함」일 때만 사용 (면세면 0%)
A25: 부가세 계수 | C25: =IF(C23="포함",1+C24,1) | E25: 판매가 ÷ 이 값 = 공급가액
A26: 월 추정매출(원) | C26: 70688000 | E26: 배달 포함 월 총매출 (부가세 처리 기준과 동일하게 입력)
A27: 월 매출 (공급가액) | C27: =ROUND(C26/C25,0) | E27: = 월 추정매출 ÷ 부가세 계수
A28: 고정비 배분율 | C28: =IF(C27>0,C20/C27,0) | E28: = 배분 대상 합계 ÷ 월 매출(공급가액)
A29: 목표 식재료 원가율 | C29: 0.3 | E29: 이하이면 ✅ 양호
A30: 주의 식재료 원가율 | C30: 0.38 | E30: 초과하면 🔴 과다

Sheet ⚠ 확인 필요
A1: ⚠ 확인 필요 항목
A2: 원본 자료에서 값이 비었거나 추정이 들어간 부분입니다. 실제 값으로 채우면 정확도가 올라갑니다.
A4: No. | B4: 구분 | C4: 메뉴 / 대상 | D4: 항목 | E4: 설명 및 조치
A5: 1 | B5: 사용량 추정 | C5: 진저 치킨 | D5: 식용유 | E5: 원본에 "적당량"으로 기재 → 20g 으로 가정. 실제값으로 수정하세요.
A6: 2 | B6: 사용량 추정 | C6: 머라이 코프타 | D6: 식용유 | E6: 원본에 "적당량"으로 기재 → 20g 으로 가정. 실제값으로 수정하세요.
A7: 3 | B7: 사용량 추정 | C7: 스프링롤 | D7: 식용유 | E7: 원본에 "적당량"으로 기재 → 20g 으로 가정. 실제값으로 수정하세요.
A8: 4 | B8: 사용량 추정 | C8: 퍼니르 퍼코다 | D8: 식용유 | E8: 원본에 "적당량"으로 기재 → 20g 으로 가정. 실제값으로 수정하세요.
A9: 5 | B9: 사용량 추정 | C9: 퍼코다 | D9: 식용유 | E9: 원본에 "적당량"으로 기재 → 20g 으로 가정. 실제값으로 수정하세요.
A10: 6 | B10: 판매가 없음 | C10: 탄두리 로티 | D10: - | E10: ④ 메뉴 원가표에서 판매가를 입력하세요. 입력 전까지 원가율은 계산되지 않습니다.
A11: 7 | B11: 사용량 추정 | C11: 탄두리 로티 | D11: 물 | E11: 원본에 "적당량"으로 기재 → 20g 으로 가정. 실제값으로 수정하세요.
A12: 8 | B12: 판매가 없음 | C12: 머턴 브리아니 | D12: - | E12: ④ 메뉴 원가표에서 판매가를 입력하세요. 입력 전까지 원가율은 계산되지 않습니다.
A13: 9 | B13: 판매가 없음 | C13: 바스마티 라이스 | D13: - | E13: ④ 메뉴 원가표에서 판매가를 입력하세요. 입력 전까지 원가율은 계산되지 않습니다.
A14: 10 | B14: 판매가 없음 | C14: 베지 플로우 | D14: - | E14: ④ 메뉴 원가표에서 판매가를 입력하세요. 입력 전까지 원가율은 계산되지 않습니다.
A15: 11 | B15: 판매가 없음 | C15: 지라 라이스 | D15: - | E15: ④ 메뉴 원가표에서 판매가를 입력하세요. 입력 전까지 원가율은 계산되지 않습니다.
A16: 12 | B16: 판매가 없음 | C16: 치킨 브리아니 | D16: - | E16: ④ 메뉴 원가표에서 판매가를 입력하세요. 입력 전까지 원가율은 계산되지 않습니다.
... A29: 25 | B29: 고정비 이중계상 조정 | C29: - | D29: 식재료 공급 계약비 | E29: 월 256,800원. 메뉴 식재료 원가에 이미 포함되어 있어 고정비 배분 대상에서 제외했습니다.
